Workbook

Sheet 2025年3月电费
A1: 宏发再生资源市场2025年3月电费收费清单
A2: 序号 | B2: 商户姓名 | C2: 分区 | D2: 电表编号 | E2: 本月电表底数 | F2: 上月电表底数 | G2: 倍率 | H2: 用电量 | I2: 单价 | J2: 电费合计 | K2: 补减项 | L2: 备注 | M2: 总计 | N2: 实收
A3: =ROW()-2 -> 1 | B3: 卯声平 | C3: 车间 | D3: 135407 | E3: 803.8 | F3: 713.8 | G3: 60 | H3: =(E3-F3)*G3 -> 5400 | I3: 1.1 | J3: =H3*I3 -> 5940 | M3: =J3+J4+K3+K4 -> 6903.6 | N3: 6904
A4: =ROW()-2 -> 2 | B4: 卯声平 | C4: 宿舍 | D4: 222933 | E4: 6333 | F4: 5457 | G4: 1 | H4: =(E4-F4)*G4 -> 876 | I4: 1.1 | J4: =H4*I4 -> 963.6
A5: =ROW()-2 -> 3 | B5: 王银全 | C5: 车间 | D5: 135406 | E5: 352.9 | F5: 303.8 | G5: 40 | H5: =(E5-F5)*G5 -> 1964 | I5: 1.1 | J5: =H5*I5 -> 2160.4 | M5: =J5+J6+K5+K6 -> 2247.3 | N5: 2247.3
A6: =ROW()-2 -> 4 | C6: 宿舍 | D6: SS101 | E6: 118 | F6: 39 | G6: 1 | H6: =(E6-F6)*G6 -> 79 | I6: 1.1 | J6: =H6*I6 -> 86.9
A7: =ROW()-2 -> 5 | B7: 谢贤祥 | C7: 车间 | D7: 135400 | E7: 10 | F7: 9 | G7: 40 | H7: =(E7-F7)*G7 -> 40 | I7: 1.1 | J7: =H7*I7 -> 44 | M7: =J7+J8+K7+K8 -> 112.2 | N7: 112
A8: =ROW()-2 -> 6 | C8: 宿舍 | D8: SS102 | E8: 323 | F8: 261 | G8: 1 | H8: =(E8-F8)*G8 -> 62 | I8: 1.1 | J8: =H8*I8 -> 68.2
A9: =ROW()-2 -> 7 | B9: 王银福 | C9: 车间 | D9: 135405 | E9: 253.4 | F9: 213.6 | G9: 40 | H9: =(E9-F9)*G9 -> 1592 | I9: 1.1 | J9: =H9*I9 -> 1751.2 | M9: =J9+K9 -> 1751.2 | N9: 1751.2
A10: =ROW()-2 -> 8 | B10: 王文奇 | C10: 车间 | D10: 135401 | E10: 50.4 | F10: 43.8 | G10: 20 | H10: =(E10-F10)*G10 -> 132 | I10: 1.1 | J10: =H10*I10 -> 145.2 | M10: =J10+K10 -> 145.2 | N10: 145.2
A11: =ROW()-2 -> 9 | B11: 李兴平 | C11: 车间一 | D11: 135402 | E11: 379.5 | F11: 320.5 | G11: 20 | H11: =(E11-F11)*G11 -> 1180 | I11: 1.1 | J11: =H11*I11 -> 1298 | M11: =J11+J12+K11+K12 -> 2296.8 | N11: 2296.8
A12: =ROW()-2 -> 10 | C12: 车间二 | D12: 135408 | E12: 144.2 | F12: 121.5 | G12: 40 | H12: =(E12-F12)*G12 -> 908 | I12: 1.1 | J12: =H12*I12 -> 998.8
A13: =ROW()-2 -> 11 | B13: 金耀 | C13: 车间 | D13: 136866 | E13: 172.8 | F13: 157 | G13: 20 | H13: =(E13-F13)*G13 -> 316 | I13: 1.1 | J13: =H13*I13 -> 347.6 | M13: =J13+K13 -> 347.6 | N13: 347.6
A14: =ROW()-2 -> 12 | B14: 代家超 | C14: 车间 | D14: 135847 | E14: 161.2 | F14: 143.9 | G14: 40 | H14: =(E14-F14)*G14 -> 692 | I14: 1.1 | J14: =H14*I14 -> 761.2 | M14: =J14+K14 -> 761.2 | N14: 761
A15: =ROW()-2 -> 13 | B15: 崔宇文 | C15: 车间 | D15: 135848 | E15: 375.2 | F15: 307.7 | G15: 40 | H15: =(E15-F15)*G15 -> 2700 | I15: 1.1 | J15: =H15*I15 -> 2970 | K15: -234 | L15: 购买钢筋欠款 | M15: =J15+K15 -> 2736 | N15: 2736
A16: =ROW()-2 -> 14 | B16: 崔玉文 | C16: 车间 | D16: 135846 | E16: 399.5 | F16: 344.4 | G16: 40 | H16: =(E16-F16)*G16 -> 2204 | I16: 1.1 | J16: =H16*I16 -> 2424.4 | M16: =J16+K16 -> 2424.4 | N16: 2424
A17: =ROW()-2 -> 15 | B17: 祖维成 | C17: 车间 | D17: 135845 | E17: 273.5 | F17: 224.4 | G17: 40 | H17: =(E17-F17)*G17 -> 1964 | I17: 1.1 | J17: =H17*I17 -> 2160.4 | M17: =J17+K17 -> 2160.4 | N17: 2160
A18: =ROW()-2 -> 16 | B18: 崔大冲 | C18: 车间 | D18: 135844 | E18: 21.6 | F18: 16 | G18: 30 | H18: =(E18-F18)*G18 -> 168 | I18: 1.1 | J18: =H18*I18 -> 184.8 | M18: =J18+K18 -> 184.8 | N18: 184
A19: =ROW()-2 -> 17 | B19: 李世坤 | C19: 车间 | D19: 135844 | E19: 26.8 | F19: 21.8 | G19: 30 | H19: =(E19-F19)*G19 -> 150 | I19: 1.1 | J19: =H19*I19 -> 165 | M19: =J19+K19 -> 165 | N19: 165
A20: =ROW()-2 -> 18 | B20: 代家虎 | C20: 车间 | D20: 135850 | E20: 150.1 | F20: 133 | G20: 30 | H20: =(E20-F20)*G20 -> 513 | I20: 1.1 | J20: =H20*I20 -> 564.3 | M20: =J20+K20 -> 564.3 | N20: 564
A21: =ROW()-2 -> 19 | B21: 代家鹏 | C21: 车间 | D21: 135358 | E21: 137.3 | F21: 119.9 | G21: 40 | H21: =(E21-F21)*G21 -> 696 | I21: 1.1 | J21: =H21*I21 -> 765.6 | M21: =J21+K21 -> 765.6 | N21: 765.6
A22: =ROW()-2 -> 20 | B22: 代家俊 | C22: 车间 | D22: 135380 | E22: 196.7 | F22: 167.5 | G22: 40 | H22: =(E22-F22)*G22 -> 1168 | I22: 1.1 | J22: =H22*I22 -> 1284.8 | M22: =J22+K22 -> 1284.8 | N22: 1284
A23: =ROW()-2 -> 21 | B23: 崔汝波 | C23: 车间 | D23: 135376 | E23: 13.1 | F23: 10.4 | G23: 40 | H23: =(E23-F23)*G23 -> 108 | I23: 1.1 | J23: =H23*I23 -> 118.8 | M23: =J23+K23 -> 118.8 | N23: 119
A24: =ROW()-2 -> 22 | B24: 崔大洪 | C24: 车间 | D24: CJ101 | E24: 214 | F24: 141 | G24: 1 | H24: =(E24-F24)*G24 -> 73 | I24: 1.1 | J24: =H24*I24 -> 80.3 | M24: =J24+K24 -> 80.3 | N24: 80.3 | P24: =N24+39.6 -> 119.9
A25: =ROW()-2 -> 23 | B25: 崔大云 | C25: 车间 | D25: CJ102 | E25: 540 | F25: 353 | G25: 1 | H25: =(E25-F25)*G25 -> 187 | I25: 1.1 | J25: =H25*I25 -> 205.7 | M25: =J25+K25 -> 205.7 | N25: 205.7
A26: =ROW()-2 -> 24 | B26: 冯成 | C26: 车间 | D26: 281917 | E26: 17.4 | F26: 0.8 | G26: 100 | H26: =(E26-F26)*G26 -> 1660 | I26: 1.1 | J26: =H26*I26 -> 1826 | M26: =J26+K26 -> 1826 | N26: 1826
A27: =ROW()-2 -> 25 | B27: 崔汝义 | C27: 车间 | D27: 136865 | E27: 164 | F27: 120.5 | G27: 20 | H27: =(E27-F27)*G27 -> 870 | I27: 1.1 | J27: =H27*I27 -> 957 | K27: =-1458.6-159.5 -> -1618.1 | L27: 抵除钢板欠款，欠：661.10 | M27: 0
A28: =ROW()-2 -> 26 | B28: 崔文交 | C28: 车间 | D28: 121780 | E28: 20.1 | F28: 14.2 | G28: 20 | H28: =(E28-F28)*G28 -> 118 | I28: 1.1 | J28: =H28*I28 -> 129.8 | M28: =J28+K28 -> 129.8 | N28: 130
A29: =ROW()-2 -> 27 | B29: 马世平 | C29: 车间 | D29: 135940 | E29: 16.7 | F29: 5.9 | G29: 30 | H29: =(E29-F29)*G29 -> 324 | I29: 1.1 | J29: =H29*I29 -> 356.4 | M29: =J29+K29 -> 356.4 | N29: 357
A30: =ROW()-2 -> 28 | B30: 崔文洪 | C30: 车间 | D30: 121780 | E30: =N35/G30+F30 -> 1625.8233 | F30: 680.7 | G30: 30 | H30: =(E30-F30)*G30 -> 28353.7 | I30: 1.1 | J30: =H30*I30 -> 31189.07 | M30: 0
A31: =ROW()-2 -> 29 | B31: 苏清友 | C31: 施工 | E31: 244 | F31: 0 | G31: 1 | H31: =(E31-F31)*G31 -> 244 | I31: 1.1 | J31: =H31*I31 -> 268.4 | M31: =J31+J32 -> 858 | N31: 858
A32: =ROW()-2 -> 30 | C32: 车间 | E32: 6.7 | F32: 0 | G32: 80 | H32: =(E32-F32)*G32 -> 536 | I32: 1.1 | J32: =H32*I32 -> 589.6
A33: 合计： | J33: =SUM(J3:J32) -> 60805.47 | M33: =SUM(M3:M32) -> 28425.4 | N33: =SUM(N3:N32) -> 28423.7
M34: 购买桶装水 | N34: 70
M35: 结余 | N35: =N33-N34 -> 28353.7

Sheet 2025年4月电费
B1: 宏发再生资源市场2025年4月电费收费清单
A2: 序号 | B2: 商户姓名 | C2: 分区 | D2: 电表编号 | E2: 本月电表底数 | F2: 上月电表底数 | G2: 倍率 | H2: 用电量 | I2: 单价 | J2: 电费合计 | K2: 补减项 | L2: 备注 | M2: 总计 | N2: 实收
A3: =ROW()-2 -> 1 | B3: 卯声平 | C3: 车间 | D3: 135407 | E3: 862 | F3: =VLOOKUP(D3,'2025年3月电费'!D:N,2,0) -> 803.8 | G3: 60 | H3: =(E3-F3)*G3 -> 3492 | I3: 1.1 | J3: =H3*I3 -> 3841.2 | K3: -300 | M3: =J3+J4+K3+K4 -> 4214.4 | N3: 4214.4
A4: =ROW()-2 -> 2 | B4: 卯声平 | C4: 宿舍 | D4: 222933 | E4: 6945 | F4: =VLOOKUP(D4,'2025年3月电费'!D:N,2,0) -> 6333 | G4: 1 | H4: =(E4-F4)*G4 -> 612 | I4: 1.1 | J4: =H4*I4 -> 673.2
A5: =ROW()-2 -> 3 | B5: 王银全 | C5: 车间 | D5: 135406 | E5: 384.8 | F5: =VLOOKUP(D5,'2025年3月电费'!D:N,2,0) -> 352.9 | G5: 40 | H5: =(E5-F5)*G5 -> 1276 | I5: 1.1 | J5: =H5*I5 -> 1403.6 | M5: =J5+J6+K5+K6 -> 1441 | N5: 1441
A6: =ROW()-2 -> 4 | C6: 宿舍 | D6: SS101 | E6: 152 | F6: =VLOOKUP(D6,'2025年3月电费'!D:N,2,0) -> 118 | G6: 1 | H6: =(E6-F6)*G6 -> 34 | I6: 1.1 | J6: =H6*I6 -> 37.4
A7: =ROW()-2 -> 5 | B7: 谢贤祥 | C7: 车间 | D7: 135400 | E7: 10.5 | F7: =VLOOKUP(D7,'2025年3月电费'!D:N,2,0) -> 10 | G7: 40 | H7: =(E7-F7)*G7 -> 20 | I7: 1.1 | J7: =H7*I7 -> 22 | M7: =J7+J8+K7+K8 -> 78.1 | N7: 78.1
A8: =ROW()-2 -> 6 | C8: 宿舍 | D8: SS102 | E8: 374 | F8: =VLOOKUP(D8,'2025年3月电费'!D:N,2,0) -> 323 | G8: 1 | H8: =(E8-F8)*G8 -> 51 | I8: 1.1 | J8: =H8*I8 -> 56.1
A9: =ROW()-2 -> 7 | B9: 王银福 | C9: 车间 | D9: 135405 | E9: 282.2 | F9: =VLOOKUP(D9,'2025年3月电费'!D:N,2,0) -> 253.4 | G9: 40 | H9: =(E9-F9)*G9 -> 1152 | I9: 1.1 | J9: =H9*I9 -> 1267.2 | M9: =J9+K9 -> 1267.2 | N9: 1267
A10: =ROW()-2 -> 8 | B10: 王文奇 | C10: 车间 | D10: 135401 | E10: 56.7 | F10: =VLOOKUP(D10,'2025年3月电费'!D:N,2,0) -> 50.4 | G10: 20 | H10: =(E10-F10)*G10 -> 126 | I10: 1.1 | J10: =H10*I10 -> 138.6 | M10: =J10+K10 -> 138.6 | N10: 139
A11: =ROW()-2 -> 9 | B11: 李兴平 | C11: 车间一 | D11: 135402 | E11: 423.9 | F11: =VLOOKUP(D11,'2025年3月电费'!D:N,2,0) -> 379.5 | G11: 20 | H11: =(E11-F11)*G11 -> 888 | I11: 1.1 | J11: =H11*I11 -> 976.8 | M11: =J11+J12+K11+K12 -> 1746.8 | N11: 1746.8
A12: =ROW()-2 -> 10 | C12: 车间二 | D12: 135408 | E12: 161.7 | F12: =VLOOKUP(D12,'2025年3月电费'!D:N,2,0) -> 144.2 | G12: 40 | H12: =(E12-F12)*G12 -> 700 | I12: 1.1 | J12: =H12*I12 -> 770
A13: =ROW()-2 -> 11 | B13: 金耀 | C13: 车间 | D13: 136866 | E13: 185.3 | F13: =VLOOKUP(D13,'2025年3月电费'!D:N,2,0) -> 172.8 | G13: 20 | H13: =(E13-F13)*G13 -> 250 | I13: 1.1 | J13: =H13*I13 -> 275 | M13: =J13+K13 -> 275 | N13: 275
A14: =ROW()-2 -> 12 | B14: 代家超 | C14: 车间 | D14: 135847 | E14: 169.8 | F14: =VLOOKUP(D14,'2025年3月电费'!D:N,2,0) -> 161.2 | G14: 40 | H14: =(E14-F14)*G14 -> 344 | I14: 1.1 | J14: =H14*I14 -> 378.4 | M14: =J14+K14 -> 378.4 | N14: 378
A15: =ROW()-2 -> 13 | B15: 崔宇文 | C15: 车间 | D15: 135848 | E15: 438 | F15: =VLOOKUP(D15,'2025年3月电费'!D:N,2,0) -> 375.2 | G15: 40 | H15: =(E15-F15)*G15 -> 2512 | I15: 1.1 | J15: =H15*I15 -> 2763.2 | M15: =J15+K15 -> 2763.2 | N15: 2763.2
A16: =ROW()-2 -> 14 | B16: 崔玉文 | C16: 车间 | D16: 135846 | E16: 445.9 | F16: =VLOOKUP(D16,'2025年3月电费'!D:N,2,0) -> 399.5 | G16: 40 | H16: =(E16-F16)*G16 -> 1856 | I16: 1.1 | J16: =H16*I16 -> 2041.6 | M16: =J16+K16 -> 2041.6 | N16: 2041.6
A17: =ROW()-2 -> 15 | B17: 祖维成 | C17: 车间 | D17: 135845 | E17: 308.3 | F17: =VLOOKUP(D17,'2025年3月电费'!D:N,2,0) -> 273.5 | G17: 40 | H17: =(E17-F17)*G17 -> 1392 | I17: 1.1 | J17: =H17*I17 -> 1531.2 | M17: =J17+K17 -> 1531.2 | N17: 1531
A18: =ROW()-2 -> 16 | B18: 崔大冲 | C18: 车间 | D18: 135844 | E18: 28 | F18: =VLOOKUP(D18,'2025年3月电费'!D:N,2,0) -> 21.6 | G18: 30 | H18: =(E18-F18)*G18 -> 192 | I18: 1.1 | J18: =H18*I18 -> 211.2 | M18: =J18+K18 -> 211.2 | N18: 211
A19: =ROW()-2 -> 17 | B19: 李世坤 | C19: 车间 | D19: 135844 | E19: 30.7 | F19: 26.8 | G19: 30 | H19: =(E19-F19)*G19 -> 117 | I19: 1.1 | J19: =H19*I19 -> 128.7 | M19: =J19+K19 -> 128.7 | N19: 128.7
A20: =ROW()-2 -> 18 | B20: 代家虎 | C20: 车间 | D20: 135850 | E20: 161.7 | F20: =VLOOKUP(D20,'2025年3月电费'!D:N,2,0) -> 150.1 | G20: 30 | H20: =(E20-F20)*G20 -> 348 | I20: 1.1 | J20: =H20*I20 -> 382.8 | M20: =J20+K20 -> 382.8 | N20: 382
A21: =ROW()-2 -> 19 | B21: 代家鹏 | C21: 车间 | D21: 135358 | E21: 153 | F21: =VLOOKUP(D21,'2025年3月电费'!D:N,2,0) -> 137.3 | G21: 40 | H21: =(E21-F21)*G21 -> 628 | I21: 1.1 | J21: =H21*I21 -> 690.8 | M21: =J21+K21 -> 690.8 | N21: 690
A22: =ROW()-2 -> 20 | B22: 代家俊 | C22: 车间 | D22: 135380 | E22: 217.7 | F22: =VLOOKUP(D22,'2025年3月电费'!D:N,2,0) -> 196.7 | G22: 40 | H22: =(E22-F22)*G22 -> 840 | I22: 1.1 | J22: =H22*I22 -> 924 | M22: =J22+K22 -> 924 | N22: 924
A23: =ROW()-2 -> 21 | B23: 崔汝波 | C23: 车间 | D23: 135376 | E23: 16.7 | F23: =VLOOKUP(D23,'2025年3月电费'!D:N,2,0) -> 13.1 | G23: 40 | H23: =(E23-F23)*G23 -> 144 | I23: 1.1 | J23: =H23*I23 -> 158.4 | M23: =J23+K23 -> 158.4 | N23: 159
A24: =ROW()-2 -> 22 | B24: 崔大洪 | C24: 车间 | D24: CJ101 | E24: 262 | F24: =VLOOKUP(D24,'2025年3月电费'!D:N,2,0) -> 214 | G24: 1 | H24: =(E24-F24)*G24 -> 48 | I24: 1.1 | J24: =H24*I24 -> 52.8 | M24: =J24+K24 -> 52.8 | N24: 52.8
A25: =ROW()-2 -> 23 | B25: 崔大云 | C25: 车间 | D25: CJ102 | E25: 860 | F25: =VLOOKUP(D25,'2025年3月电费'!D:N,2,0) -> 540 | G25: 1 | H25: =(E25-F25)*G25 -> 320 | I25: 1.1 | J25: =H25*I25 -> 352 | M25: =J25+K25 -> 352 | N25: 352
A26: =ROW()-2 -> 24 | B26: 冯成 | C26: 车间 | D26: 281917 | E26: 25.8 | F26: =VLOOKUP(D26,'2025年3月电费'!D:N,2,0) -> 17.4 | G26: 100 | H26: =(E26-F26)*G26 -> 840 | I26: 1.1 | J26: =H26*I26 -> 924 | M26: =J26+K26 -> 924 | N26: 924
A27: =ROW()-2 -> 25 | B27: 崔汝义 | C27: 车间 | D27: 136865 | E27: 214.5 | F27: =VLOOKUP(D27,'2025年3月电费'!D:N,2,0) -> 164 | G27: 20 | H27: =(E27-F27)*G27 -> 1010 | I27: 1.1 | J27: =H27*I27 -> 1111 | K27: -661.1 | L27: 抵除钢板欠款 | M27: =J27+K27 -> 449.9 | N27: 449.9
A28: =ROW()-2 -> 26 | B28: 崔文交 | C28: 车间 | D28: 121780 | E28: 29 | F28: =VLOOKUP(D28,'2025年3月电费'!D:N,2,0) -> 20.1 | G28: 20 | H28: =(E28-F28)*G28 -> 178 | I28: 1.1 | J28: =H28*I28 -> 195.8 | M28: =J28+K28 -> 195.8 | N28: 195.8
A29: =ROW()-2 -> 27 | B29: 马世平 | C29: 车间 | D29: 135940 | E29: 24.7 | F29: =VLOOKUP(D29,'2025年3月电费'!D:N,2,0) -> 16.7 | G29: 30 | H29: =(E29-F29)*G29 -> 240 | I29: 1.1 | J29: =H29*I29 -> 264 | M29: =J29+K29 -> 264 | N29: 264
A30: =ROW()-2 -> 28 | B30: 崔文洪 | C30: 车间 | D30: 121780 | E30: =1625.82+270.73 -> 1896.55 | F30: 1625.82 | G30: 30 | H30: =(E30-F30)*G30 -> 8121.9 | I30: 1.1 | J30: 0 | M30: =J30+K30 -> 0
A31: =ROW()-2 -> 29 | B31: 苏清友 | C31: 施工 | E31: 256 | F31: 244 | G31: 1 | H31: =(E31-F31)*G31 -> 12 | I31: 1.1 | J31: =H31*I31 -> 13.2 | M31: =J31+J32 -> 12826 | N31: 12826
A32: =ROW()-2 -> 30 | C32: 车间 | E32: 152.3 | F32: 6.7 | G32: 80 | H32: =(E32-F32)*G32 -> 11648 | I32: 1.1 | J32: =H32*I32 -> 12812.8
A33: 合计： | J33: =SUM(J3:J32) -> 34397 | M33: =SUM(M3:M32) -> 33435.9 | N33: =SUM(N3:N32) -> 33434.3
A34: 支付饭钱： | N34: 1900
E35: 挖机烟钱 | N35: =24*4 -> 96
E36: 余波华新烟钱 | N36: =50*2 -> 100
E37: 鞋套+安全绳 | N37: 110
E38: 小蒋烟钱 | N38: 200
E39: 餐费(抢修电缆，晚餐两次) | N39: 470
E40: 崔文洪 | N40: 2000
...

Sheet 2025年5月电费
A1: 宏发再生资源市场2025年5月电费收费清单
A2: 序号 | B2: 商户姓名 | C2: 分区 | D2: 电表编号 | E2: 本月电表底数 | F2: 上月电表底数 | G2: 倍率 | H2: 用电量 | I2: 单价 | J2: 电费合计 | K2: 补减项 | L2: 备注 | M2: 总计 | N2: 实收
A3: =ROW()-2 -> 1 | B3: 卯声平 | C3: 车间 | D3: 135407 | E3: 896 | F3: =VLOOKUP(D3,'2025年4月电费'!D:N,2,0) -> 862 | G3: 60 | H3: =(E3-F3)*G3 -> 2040 | I3: 1.1 | J3: =H3*I3 -> 2244 | M3: =J3+J4+K3+K4 -> 2814.9 | N3: 2815
A4: =ROW()-2 -> 2 | B4: 卯声平 | C4: 宿舍 | D4: 222933 | E4: 7464 | F4: =VLOOKUP(D4,'2025年4月电费'!D:N,2,0) -> 6945 | G4: 1 | H4: =(E4-F4)*G4 -> 519 | I4: 1.1 | J4: =H4*I4 -> 570.9
A5: =ROW()-2 -> 3 | B5: 王银全 | C5: 车间 | D5: 135406 | E5: 412.6 | F5: =VLOOKUP(D5,'2025年4月电费'!D:N,2,0) -> 384.8 | G5: 40 | H5: =(E5-F5)*G5 -> 1112 | I5: 1.1 | J5: =H5*I5 -> 1223.2 | M5: =J5+J6+K5+K6 -> 1237.5 | N5: 1237
C6: 宿舍 | D6: SS101 | E6: 165 | F6: =VLOOKUP(D6,'2025年4月电费'!D:N,2,0) -> 152 | G6: 1 | H6: =(E6-F6)*G6 -> 13 | I6: 1.1 | J6: =H6*I6 -> 14.3
A7: =ROW()-2 -> 5 | B7: 谢贤祥 | C7: 车间 | D7: 135400 | E7: 11.1 | F7: =VLOOKUP(D7,'2025年4月电费'!D:N,2,0) -> 10.5 | G7: 40 | H7: =(E7-F7)*G7 -> 24 | I7: 1.1 | J7: =H7*I7 -> 26.4 | M7: =J7+J8+K7+K8 -> 72.6 | N7: 72
C8: 宿舍 | D8: SS102 | E8: 416 | F8: =VLOOKUP(D8,'2025年4月电费'!D:N,2,0) -> 374 | G8: 1 | H8: =(E8-F8)*G8 -> 42 | I8: 1.1 | J8: =H8*I8 -> 46.2
A9: =ROW()-2 -> 7 | B9: 王银福 | C9: 车间 | D9: 135405 | E9: 306.3 | F9: =VLOOKUP(D9,'2025年4月电费'!D:N,2,0) -> 282.2 | G9: 40 | H9: =(E9-F9)*G9 -> 964 | I9: 1.1 | J9: =H9*I9 -> 1060.4 | M9: =J9+K9 -> 1060.4 | N9: 1060.4
A10: =ROW()-2 -> 8 | B10: 王文奇 | C10: 车间 | D10: 135401 | E10: 59.8 | F10: =VLOOKUP(D10,'2025年4月电费'!D:N,2,0) -> 56.7 | G10: 20 | H10: =(E10-F10)*G10 -> 62 | I10: 1.1 | J10: =H10*I10 -> 68.2 | M10: =J10+K10 -> 68.2 | N10: 68.2
A11: =ROW()-2 -> 9 | B11: 李兴平 | C11: 车间一 | D11: 135402 | E11: 456.6 | F11: =VLOOKUP(D11,'2025年4月电费'!D:N,2,0) -> 423.9 | G11: 20 | H11: =(E11-F11)*G11 -> 654 | I11: 1.1 | J11: =H11*I11 -> 719.4 | K11: -242.5 | L11: 购买铁板 | M11: =J11+J12+K11+K12 -> 1255.7 | N11: 1255.7
C12: 车间二 | D12: 135408 | E12: 179.4 | F12: =VLOOKUP(D12,'2025年4月电费'!D:N,2,0) -> 161.7 | G12: 40 | H12: =(E12-F12)*G12 -> 708 | I12: 1.1 | J12: =H12*I12 -> 778.8
A13: =ROW()-2 -> 11 | B13: 金耀 | C13: 车间 | D13: 136866 | E13: 197.5 | F13: =VLOOKUP(D13,'2025年4月电费'!D:N,2,0) -> 185.3 | G13: 20 | H13: =(E13-F13)*G13 -> 244 | I13: 1.1 | J13: =H13*I13 -> 268.4 | M13: =J13+K13 -> 268.4 | N13: 268.4
A14: =ROW()-2 -> 12 | B14: 代家超 | C14: 车间 | D14: 135847 | E14: 177.3 | F14: =VLOOKUP(D14,'2025年4月电费'!D:N,2,0) -> 169.8 | G14: 40 | H14: =(E14-F14)*G14 -> 300 | I14: 1.1 | J14: =H14*I14 -> 330 | M14: =J14+K14 -> 330 | N14: 330
A15: =ROW()-2 -> 13 | B15: 崔宇文 | C15: 车间 | D15: 135848 | E15: 487.6 | F15: =VLOOKUP(D15,'2025年4月电费'!D:N,2,0) -> 438 | G15: 40 | H15: =(E15-F15)*G15 -> 1984 | I15: 1.1 | J15: =H15*I15 -> 2182.4 | K15: -494 | L15: 购买铁板 | M15: =J15+K15 -> 1688.4 | N15: 1688.4
A16: =ROW()-2 -> 14 | B16: 崔玉文 | C16: 车间 | D16: 135846 | E16: 485 | F16: =VLOOKUP(D16,'2025年4月电费'!D:N,2,0) -> 445.9 | G16: 40 | H16: =(E16-F16)*G16 -> 1564 | I16: 1.1 | J16: =H16*I16 -> 1720.4 | M16: =J16+K16 -> 1720.4 | N16: 1720.4
A17: =ROW()-2 -> 15 | B17: 祖维成 | C17: 车间 | D17: 135845 | E17: 337.5 | F17: =VLOOKUP(D17,'2025年4月电费'!D:N,2,0) -> 308.3 | G17: 40 | H17: =(E17-F17)*G17 -> 1168 | I17: 1.1 | J17: =H17*I17 -> 1284.8 | M17: =J17+K17 -> 1284.8 | N17: 1284
A18: =ROW()-2 -> 16 | B18: 崔大冲 | C18: 车间 | D18: 135844 | E18: 35.2 | F18: =VLOOKUP(D18,'2025年4月电费'!D:N,2,0) -> 28 | G18: 30 | H18: =(E18-F18)*G18 -> 216 | I18: 1.1 | J18: =H18*I18 -> 237.6 | M18: =J18+K18 -> 237.6 | N18: 237.6
A19: =ROW()-2 -> 17 | B19: 李世坤 | C19: 车间 | D19: 135844 | E19: 36.1 | F19: =VLOOKUP(D19,'2025年4月电费'!D:N,2,0) -> 28 | G19: 30 | H19: =(E19-F19)*G19 -> 243 | I19: 1.1 | J19: =H19*I19 -> 267.3 | M19: =J19+K19 -> 267.3 | N19: 267
A20: =ROW()-2 -> 18 | B20: 代家虎 | C20: 车间 | D20: 135850 | E20: 169.7 | F20: =VLOOKUP(D20,'2025年4月电费'!D:N,2,0) -> 161.7 | G20: 30 | H20: =(E20-F20)*G20 -> 240 | I20: 1.1 | J20: =H20*I20 -> 264 | M20: =J20+K20 -> 264 | N20: 264
A21: =ROW()-2 -> 19 | B21: 代家鹏 | C21: 车间 | D21: 135358 | E21: 167.2 | F21: =VLOOKUP(D21,'2025年4月电费'!D:N,2,0) -> 153 | G21: 40 | H21: =(E21-F21)*G21 -> 568 | I21: 1.1 | J21: =H21*I21 -> 624.8 | M21: =J21+K21 -> 624.8 | N21: 624
A22: =ROW()-2 -> 20 | B22: 代家俊 | C22: 车间 | D22: 135380 | E22: 236.4 | F22: =VLOOKUP(D22,'2025年4月电费'!D:N,2,0) -> 217.7 | G22: 40 | H22: =(E22-F22)*G22 -> 748 | I22: 1.1 | J22: =H22*I22 -> 822.8 | M22: =J22+K22 -> 822.8 | N22: 822
A23: =ROW()-2 -> 21 | B23: 崔汝波 | C23: 车间 | D23: 135376 | E23: 20.2 | F23: =VLOOKUP(D23,'2025年4月电费'!D:N,2,0) -> 16.7 | G23: 40 | H23: =(E23-F23)*G23 -> 140 | I23: 1.1 | J23: =H23*I23 -> 154 | M23: =J23+K23 -> 154 | N23: 154
A24: =ROW()-2 -> 22 | B24: 崔大洪 | C24: 车间 | D24: CJ101 | E24: 315 | F24: =VLOOKUP(D24,'2025年4月电费'!D:N,2,0) -> 262 | G24: 1 | H24: =(E24-F24)*G24 -> 53 | I24: 1.1 | J24: =H24*I24 -> 58.3 | M24: =J24+K24 -> 58.3 | N24: 58.3
A25: =ROW()-2 -> 23 | B25: 崔大云 | C25: 车间 | D25: CJ102 | E25: 1123 | F25: =VLOOKUP(D25,'2025年4月电费'!D:N,2,0) -> 860 | G25: 1 | H25: =(E25-F25)*G25 -> 263 | I25: 1.1 | J25: =H25*I25 -> 289.3 | M25: =J25+K25 -> 289.3 | N25: 289.3
A26: =ROW()-2 -> 24 | B26: 冯成 | C26: 车间 | D26: 281917 | E26: 30.6 | F26: =VLOOKUP(D26,'2025年4月电费'!D:N,2,0) -> 25.8 | G26: 100 | H26: =(E26-F26)*G26 -> 480 | I26: 1.1 | J26: =H26*I26 -> 528 | M26: =J26+K26 -> 528 | N26: 528
A27: =ROW()-2 -> 25 | B27: 崔汝义 | C27: 车间 | D27: 136865 | E27: 243.6 | F27: =VLOOKUP(D27,'2025年4月电费'!D:N,2,0) -> 214.5 | G27: 20 | H27: =(E27-F27)*G27 -> 582 | I27: 1.1 | J27: =H27*I27 -> 640.2 | M27: =J27+K27 -> 640.2 | N27: 640.2
A28: =ROW()-2 -> 26 | B28: 崔文交 | C28: 车间 | D28: 121780 | E28: 35.8 | F28: =VLOOKUP(D28,'2025年4月电费'!D:N,2,0) -> 29 | G28: 20 | H28: =(E28-F28)*G28 -> 136 | I28: 1.1 | J28: =H28*I28 -> 149.6 | M28: =J28+K28 -> 149.6 | N28: 150
A29: =ROW()-2 -> 27 | B29: 马世平 | C29: 车间 | D29: 135940 | E29: 29.7 | F29: =VLOOKUP(D29,'2025年4月电费'!D:N,2,0) -> 24.7 | G29: 30 | H29: =(E29-F29)*G29 -> 150 | I29: 1.1 | J29: =H29*I29 -> 165 | M29: =J29+K29 -> 165 | N29: 165
A30: =ROW()-2 -> 28 | B30: 崔文洪 | C30: 车间 | D30: 121780 | E30: 2097.6 | F30: =1625.82+270.73 -> 1896.55 | G30: 30 | H30: =(E30-F30)*G30 -> 6031.5 | I30: 1.1 | J30: =H30*I30 -> 6634.65 | M30: 0
A31: =ROW()-2 -> 29 | B31: 苏清友 | C31: 车间 | D31: 134768 | E31: 284.8 | F31: 152.3 | G31: 80 | H31: =(E31-F31)*G31 -> 10600 | I31: 1.1 | J31: =H31*I31 -> 11660 | M31: =J31+K31 -> 11660 | N31: 11660
A32: 合计： | J32: =SUM(J3:J31) -> 35033.35 | M32: =SUM(M3:M31) -> 27662.2 | N32: =SUM(N3:N31) -> 27658.9
A34: 支付饭钱： | N34: 2160
A35: 桶装水： | N35: 140
A36: 草酸：10*10kg | N36: 219
A37: 大号垃圾袋：60只*21包 | N37: =21*7.99 -> 167.79
A38: 电缆：3*185+2*95铝芯线46米 | N38: 2740
A39: 宽带费： | N39: 1000
A40: 电费： | N40: 35622.89
A41: 变压器至苏总电缆沟清理： | N41: 1700
...

Sheet 抄表数据临时表
A1: 商户姓名 | B1: 本月抄表电量 | C1: 上月抄表电量 | D1: 倍率 | E1: 实际用电量 | F1: 单价 | G1: 电费金额 | H1: 表号
A2: 食堂厨房 | B2: 6110 | C2: 6110 | D2: 1 | E2: =(B2-C2)*D2 -> 0 | F2: 1.1 | G2: =ROUNDUP((E2*F2),0) -> 0 | H2: 763170
A3: 食堂餐厅 | B3: 4022 | C3: 4022 | D3: 1 | E3: =(B3-C3)*D3 -> 0 | F3: 1.1 | G3: =ROUNDUP((E3*F3),0) -> 0 | H3: 272501
A4: 卯声平 | B4: 803.8 | C4: 713.8 | D4: 60 | E4: =(B4-C4)*D4 -> 5400 | F4: 1.1 | G4: =ROUNDUP((E4*F4),0) -> 5940 | H4: 135407
A5: 卯声平宿舍 | B5: 6333 | C5: 5457 | D5: 1 | E5: =(B5-C5)*D5 -> 876 | F5: 1.1 | G5: =ROUNDUP((E5*F5),0) -> 964 | H5: 222933
A6: 王银全车间 | B6: 352.9 | C6: 303.8 | D6: 40 | E6: =(B6-C6)*D6 -> 1964 | F6: 1.1 | G6: =ROUNDUP((E6*F6),0) -> 2161 | H6: 135406
A7: 王银全宿舍 | B7: 118 | C7: 39 | D7: 1 | E7: =(B7-C7)*D7 -> 79 | F7: 1.1 | G7: =ROUNDUP((E7*F7),0) -> 87 | H7: 无
B8: 2025年3月3日入住，3月17日入住，共两间300元每月。
A9: 谢贤祥 | B9: 10 | C9: 9 | D9: 40 | E9: =(B9-C9)*D9 -> 40 | F9: 1.1 | G9: =ROUNDUP((E9*F9),0) -> 44 | H9: 135400
A10: 谢贤祥宿舍 | B10: 323 | C10: 261 | D10: 1 | E10: =(B10-C10)*D10 -> 62 | F10: 1.1 | G10: =ROUNDUP((E10*F10),0) -> 69 | H10: 无
A11: 王银福 | B11: 253.4 | C11: 213.6 | D11: 40 | E11: =(B11-C11)*D11 -> 1592 | F11: 1.1 | G11: =ROUNDUP((E11*F11),0) -> 1752 | H11: 135405
A12: 王文奇 | B12: 50.4 | C12: 43.8 | D12: 20 | E12: =(B12-C12)*D12 -> 132 | F12: 1.1 | G12: =ROUNDUP((E12*F12),0) -> 146 | H12: 135401
A13: 李兴平1 | B13: 379.5 | C13: 320.5 | D13: 20 | E13: =(B13-C13)*D13 -> 1180 | F13: 1.1 | G13: =ROUNDUP((E13*F13),0) -> 1298 | H13: 135402
A14: 李兴平2 | B14: 144.2 | C14: 121.5 | D14: 40 | E14: =(B14-C14)*D14 -> 908 | F14: 1.1 | G14: =ROUNDUP((E14*F14),0) -> 999 | H14: 135408
A15: 金 耀 | B15: 172.8 | C15: 157 | D15: 20 | E15: =(B15-C15)*D15 -> 316 | F15: 1.1 | G15: =ROUNDUP((E15*F15),0) -> 348 | H15: 136866
A16: 办公楼 | B16: 1510 | C16: 1049 | D16: 1 | E16: =(B16-C16)*D16 -> 461 | H16: 无
A17: 张祥恩 | B17: 2113 | C17: 1630 | D17: 1 | E17: =(B17-C17)*D17 -> 483 | H17: 无
A18: 磅房门卫 | B18: 3810 | C18: 2900 | D18: 1 | E18: =(B18-C18)*D18 -> 910 | H18: 无
A19: 深井泵 | B19: 2532 | C19: 1895 | D19: 1 | E19: =(B19-C19)*D19 -> 637 | H19: 无
A20: 增压泵 | B20: 1415 | C20: 1031 | D20: 1 | E20: =(B20-C20)*D20 -> 384 | H20: 无
A21: 商家总 | E21: =SUM(E2:E15) -> 12549
A22: 总 表 | B22: 338.3 | C22: 297.7 | D22: 400 | E22: =(B22-C22)*D22 -> 16240 | H22: 135404
A23: 代家超 | B23: 161.2 | C23: 143.9 | D23: 40 | E23: =(B23-C23)*D23 -> 692 | F23: 1.1 | G23: =ROUNDUP((E23*F23),0) -> 762 | H23: 135847
A24: 崔宇文 | B24: 375.2 | C24: 307.7 | D24: 40 | E24: =(B24-C24)*D24 -> 2700 | F24: 1.1 | G24: =ROUNDUP((E24*F24),0) -> 2970 | H24: 135848
B25: 钢筋做排污管支架，90公斤，2.6元每公斤，共234元
A26: 崔玉文 | B26: 399.5 | C26: 344.4 | D26: 40 | E26: =(B26-C26)*D26 -> 2204 | F26: 1.1 | G26: =ROUNDUP((E26*F26),0) -> 2425 | H26: 135846
A27: 祖维成 | B27: 273.5 | C27: 224.4 | D27: 40 | E27: =(B27-C27)*D27 -> 1964 | F27: 1.1 | G27: =ROUNDUP((E27*F27),0) -> 2161 | H27: 135845
A28: 崔大冲 | B28: 21.6 | C28: 16 | D28: 30 | E28: =(B28-C28)*D28 -> 168 | F28: 1.1 | G28: =ROUNDUP((E28*F28),0) -> 185 | H28: 135844
A29: 李世坤 | B29: 26.8 | C29: 21.8 | D29: 30 | E29: =(B29-C29)*D29 -> 150 | F29: 1.1 | G29: =ROUNDUP((E29*F29),0) -> 165 | H29: 135851
A30: 代家虎 | B30: 150.1 | C30: 133 | D30: 30 | E30: =(B30-C30)*D30 -> 513 | F30: 1.1 | G30: =ROUNDUP((E30*F30),0) -> 565 | H30: 135850
A31: 代家鹏 | B31: 137.3 | C31: 119.9 | D31: 40 | E31: =(B31-C31)*D31 -> 696 | F31: 1.1 | G31: =ROUNDUP((E31*F31),0) -> 766 | H31: 135358
A32: 代家俊 | B32: 196.7 | C32: 167.5 | D32: 40 | E32: =(B32-C32)*D32 -> 1168 | F32: 1.1 | G32: =ROUNDUP((E32*F32),0) -> 1285 | H32: 135380
A33: 崔汝波 | B33: 13.1 | C33: 10.4 | D33: 40 | E33: =(B33-C33)*D33 -> 108 | F33: 1.1 | G33: =ROUNDUP((E33*F33),0) -> 119 | H33: 135376
A34: 崔大洪 | B34: 214 | C34: 141 | D34: 1 | E34: =(B34-C34)*D34 -> 73 | F34: 1.1 | G34: =ROUNDUP((E34*F34),0) -> 81 | H34: 无
A35: 崔大云 | B35: 540 | C35: 353 | D35: 1 | E35: =(B35-C35)*D35 -> 187 | F35: 1.1 | G35: =ROUNDUP((E35*F35),0) -> 206 | H35: 无
A36: 冯 成 | B36: 17.4 | C36: 0.8 | D36: 100 | E36: =(B36-C36)*D36 -> 1660 | F36: 1.1 | G36: =ROUNDUP((E36*F36),0) -> 1826 | H36: 281917
A37: 消防泵 | B37: 120 | C37: 79 | D37: 1 | E37: =(B37-C37)*D37 -> 41 | H37: 无
A38: 商家总 | E38: =SUM(E23:E36) -> 12283
A39: 总 表 | B39: 178 | C39: 147.4 | D39: 400 | E39: =(B39-C39)*D39 -> 12240 | H39: 135849
A40: 崔汝义 | B40: 164 | C40: 120.5 | D40: 20 | E40: =(B40-C40)*D40 -> 870 | F40: 1.1 | G40: =ROUNDUP((E40*F40),0) -> 957 | H40: 136865
...

Sheet 2025年6月水电费
A1: 宏发再生资源市场2025年6月水电费收费清单
A2: 序号 | B2: 商户姓名 | C2: 分区 | D2: 电表编号 | E2: 本月电表底数 | F2: 上月电表底数 | G2: 倍率 | H2: 用电量 | I2: 电费单价 | J2: 电费合计 | K2: 上月水表底数 | L2: 本月水表底数 | M2: 水费单价 | N2: 水费合计 | O2: 补减项 | P2: 备注 | Q2: 总计 | R2: 实收
A3: =ROW()-2 -> 1 | B3: 卯声平 | C3: 车间 | D3: 135407 | E3: 1008.7 | F3: 896 | G3: 60 | H3: =(E3-F3)*G3 -> 6762 | I3: 1.1 | J3: =H3*I3 -> 7438.2 | K3: 76 | L3: 146 | M3: 4.4 | N3: =(L3-K3)*M3 -> 308 | Q3: =J3+J4+O3+O4+N3+N4 -> 8636.1 | R3: 8636
C4: 宿舍 | D4: 222933 | E4: 8021 | F4: 7464 | G4: 1 | H4: =(E4-F4)*G4 -> 557 | I4: 1.1 | J4: =H4*I4 -> 612.7 | K4: 119 | L4: 182 | M4: 4.4 | N4: =(L4-K4)*M4 -> 277.2
A5: 2 | B5: 王银全 | C5: 车间 | D5: 135406 | E5: 442.1 | F5: 412.6 | G5: 40 | H5: =(E5-F5)*G5 -> 1180 | I5: 1.1 | J5: =H5*I5 -> 1298 | K5: 94 | L5: 164 | M5: 4.4 | N5: =(L5-K5)*M5 -> 308 | Q5: =J5+J6+O5+O6+N5+N6 -> 1626.9 | R5: 1626
C6: 宿舍 | D6: SS101 | E6: 184 | F6: 165 | G6: 1 | H6: =(E6-F6)*G6 -> 19 | I6: 1.1 | J6: =H6*I6 -> 20.9 | K6: 0 | L6: 0 | M6: 4.4 | N6: =(L6-K6)*M6 -> 0
A7: 3 | B7: 谢贤祥 | C7: 车间 | D7: 135400 | E7: 11.7 | F7: 11.1 | G7: 40 | H7: =(E7-F7)*G7 -> 24 | I7: 1.1 | J7: =H7*I7 -> 26.4 | K7: 44 | L7: 55 | M7: 4.4 | N7: =(L7-K7)*M7 -> 48.4 | Q7: =J7+J8+O7+O8+N7+N8 -> 157.3 | R7: 157.3
C8: 宿舍 | D8: SS102 | E8: 459 | F8: 416 | G8: 1 | H8: =(E8-F8)*G8 -> 43 | I8: 1.1 | J8: =H8*I8 -> 47.3 | K8: 5 | L8: 13 | M8: 4.4 | N8: =(L8-K8)*M8 -> 35.2
A9: 4 | B9: 王银福 | C9: 车间 | D9: 135405 | E9: 335.7 | F9: 306.3 | G9: 40 | H9: =(E9-F9)*G9 -> 1176 | I9: 1.1 | J9: =H9*I9 -> 1293.6 | K9: 92 | L9: 155 | M9: 4.4 | N9: =(L9-K9)*M9 -> 277.2 | Q9: =J9+O9+N9 -> 1570.8 | R9: 1293.6 | S9: =Q9-R9 -> 277.2
A10: 5 | B10: 王文奇 | C10: 车间 | D10: 135401 | E10: 64 | F10: 59.8 | G10: 20 | H10: =(E10-F10)*G10 -> 84 | I10: 1.1 | J10: =H10*I10 -> 92.4 | K10: 7 | L10: 8 | M10: 4.4 | N10: =(L10-K10)*M10 -> 4.4 | Q10: =J10+O10+N10 -> 96.8 | R10: 92.4
A11: 6 | B11: 李兴平 | C11: 车间一 | D11: 135402 | E11: 502.8 | F11: 456.6 | G11: 20 | H11: =(E11-F11)*G11 -> 924 | I11: 1.1 | J11: =H11*I11 -> 1016.4 | K11: 101 | L11: 166 | M11: 4.4 | N11: =(L11-K11)*M11 -> 286 | Q11: =J11+J12+O11+O12+N11+N12 -> 2283.6 | R11: 2283.6
C12: 车间二 | D12: 135408 | E12: 201.7 | F12: 179.4 | G12: 40 | H12: =(E12-F12)*G12 -> 892 | I12: 1.1 | J12: =H12*I12 -> 981.2 | K12: 0 | L12: 0 | M12: 4.4 | N12: =(L12-K12)*M12 -> 0
A13: 7 | B13: 金耀 | C13: 车间 | D13: 136866 | E13: 210.1 | F13: 197.5 | G13: 20 | H13: =(E13-F13)*G13 -> 252 | I13: 1.1 | J13: =H13*I13 -> 277.2 | K13: 13 | L13: 20 | M13: 4.4 | N13: =(L13-K13)*M13 -> 30.8 | Q13: =J13+O13+N13 -> 308 | R13: 308
A14: 8 | B14: 代家超 | C14: 车间 | D14: 135847 | E14: 187.6 | F14: 177.3 | G14: 40 | H14: =(E14-F14)*G14 -> 412 | I14: 1.1 | J14: =H14*I14 -> 453.2 | K14: 43 | L14: 61 | M14: 4.4 | N14: =(L14-K14)*M14 -> 79.2 | Q14: =J14+O14+N14 -> 532.4 | R14: 532 | S14: 45848
A15: 9 | B15: 崔宇文 | C15: 车间 | D15: 135848 | E15: 545.8 | F15: 487.6 | G15: 40 | H15: =(E15-F15)*G15 -> 2328 | I15: 1.1 | J15: =H15*I15 -> 2560.8 | K15: 10 | L15: 18 | M15: 4.4 | N15: =(L15-K15)*M15 -> 35.2 | Q15: =J15+O15+N15 -> 2596 | R15: 2596
A16: 10 | B16: 崔玉文 | C16: 车间 | D16: 135846 | E16: 532.6 | F16: 485 | G16: 40 | H16: =(E16-F16)*G16 -> 1904 | I16: 1.1 | J16: =H16*I16 -> 2094.4 | K16: 3 | L16: 5 | M16: 4.4 | N16: =(L16-K16)*M16 -> 8.8 | Q16: =J16+O16+N16 -> 2103.2 | R16: 2103
A17: 11 | B17: 祖维成 | C17: 车间 | D17: 135845 | E17: 366.5 | F17: 337.5 | G17: 40 | H17: =(E17-F17)*G17 -> 1160 | I17: 1.1 | J17: =H17*I17 -> 1276 | K17: 80 | L17: 155 | M17: 4.4 | N17: =(L17-K17)*M17 -> 330 | Q17: =J17+O17+N17 -> 1606 | R17: 1606
A18: 12 | B18: 崔大冲 | C18: 车间 | D18: 135844 | E18: 41.9 | F18: 35.2 | G18: 30 | H18: =(E18-F18)*G18 -> 201 | I18: 1.1 | J18: =H18*I18 -> 221.1 | K18: 3 | L18: 17 | M18: 4.4 | N18: =(L18-K18)*M18 -> 61.6 | Q18: =J18+O18+N18 -> 282.7 | R18: 280.27
A19: 13 | B19: 李世坤 | C19: 车间 | D19: 135844 | E19: 41.2 | F19: 36.1 | G19: 30 | H19: =(E19-F19)*G19 -> 153 | I19: 1.1 | J19: =H19*I19 -> 168.3 | K19: 3 | L19: 19 | M19: 4.4 | N19: =(L19-K19)*M19 -> 70.4 | Q19: =J19+O19+N19 -> 238.7 | R19: 238.7 | S19: 45848
A20: 14 | B20: 代家虎 | C20: 车间 | D20: 135850 | E20: 179.1 | F20: 169.7 | G20: 30 | H20: =(E20-F20)*G20 -> 282 | I20: 1.1 | J20: =H20*I20 -> 310.2 | K20: 24 | L20: 37 | M20: 4.4 | N20: =(L20-K20)*M20 -> 57.2 | Q20: =J20+O20+N20 -> 367.4 | R20: 367 | S20: 45848
A21: 15 | B21: 代家鹏 | C21: 车间 | D21: 135358 | E21: 183.5 | F21: 167.2 | G21: 40 | H21: =(E21-F21)*G21 -> 652 | I21: 1.1 | J21: =H21*I21 -> 717.2 | K21: 53 | L21: 105 | M21: 4.4 | N21: =(L21-K21)*M21 -> 228.8 | Q21: =J21+O21+N21 -> 946 | R21: 946
A22: 16 | B22: 代家俊 | C22: 车间 | D22: 135380 | E22: 256.6 | F22: 236.4 | G22: 40 | H22: =(E22-F22)*G22 -> 808 | I22: 1.1 | J22: =H22*I22 -> 888.8 | K22: 49 | L22: 110 | M22: 4.4 | N22: =(L22-K22)*M22 -> 268.4 | Q22: =J22+O22+N22 -> 1157.2 | R22: 1157
A23: 17 | B23: 崔汝波 | C23: 车间 | D23: 135376 | E23: 24.2 | F23: 20.2 | G23: 40 | H23: =(E23-F23)*G23 -> 160 | I23: 1.1 | J23: =H23*I23 -> 176 | K23: 42 | L23: 59 | M23: 4.4 | N23: =(L23-K23)*M23 -> 74.8 | Q23: =J23+O23+N23 -> 250.8 | R23: =75+176 -> 251 | S23: 45848
A24: 18 | B24: 崔大洪 | C24: 车间 | D24: CJ101 | E24: 367 | F24: 315 | G24: 1 | H24: =(E24-F24)*G24 -> 52 | I24: 1.1 | J24: =H24*I24 -> 57.2 | K24: 5 | L24: 9 | M24: 4.4 | N24: =(L24-K24)*M24 -> 17.6 | Q24: =J24+O24+N24 -> 74.8 | R24: 75
A25: 19 | B25: 崔大云 | C25: 车间 | D25: CJ102 | E25: 1491 | F25: 1123 | G25: 1 | H25: =(E25-F25)*G25 -> 368 | I25: 1.1 | J25: =H25*I25 -> 404.8 | K25: 12 | L25: 38 | M25: 4.4 | N25: =(L25-K25)*M25 -> 114.4 | Q25: =J25+O25+N25 -> 519.2 | R25: 519.2
A26: 20 | B26: 冯成 | C26: 车间 | D26: 281917 | E26: 42.1 | F26: 30.6 | G26: 100 | H26: =(E26-F26)*G26 -> 1150 | I26: 1.1 | J26: =H26*I26 -> 1265 | K26: 0 | L26: 9 | M26: 4.4 | N26: =(L26-K26)*M26 -> 39.6 | Q26: =J26+O26+N26 -> 1304.6 | R26: 1304.6
A27: 21 | B27: 崔汝义 | C27: 车间 | D27: 136865 | E27: 267.5 | F27: 243.6 | G27: 20 | H27: =(E27-F27)*G27 -> 478 | I27: 1.1 | J27: =H27*I27 -> 525.8 | K27: 2 | L27: 4 | M27: 4.4 | N27: =(L27-K27)*M27 -> 8.8 | Q27: =J27+O27+N27 -> 534.6 | R27: 534.6
A28: 22 | B28: 崔文交 | C28: 车间 | D28: 121780 | E28: 45.6 | F28: 35.8 | G28: 20 | H28: =(E28-F28)*G28 -> 196 | I28: 1.1 | J28: =H28*I28 -> 215.6 | K28: 7 | L28: 38 | M28: 4.4 | N28: =(L28-K28)*M28 -> 136.4 | Q28: =J28+O28+N28 -> 352 | R28: 352 | S28: 45848
A29: 23 | B29: 马世平 | C29: 车间 | D29: 135940 | E29: 33.9 | F29: 29.7 | G29: 30 | H29: =(E29-F29)*G29 -> 126 | I29: 1.1 | J29: =H29*I29 -> 138.6 | K29: 0 | L29: 3 | M29: 4.4 | N29: =(L29-K29)*M29 -> 13.2 | Q29: =J29+O29+N29 -> 151.8 | R29: 152
A30: 24 | B30: 崔文洪 | C30: 生活 | K30: 126 | L30: 258 | M30: 4.4 | N30: =(L30-K30)*M30 -> 580.8 | Q30: =J30+O30+J31+N30+N31+O31 -> 849.2 | R30: 850
C31: 车间 | D31: 121780 | E31: 2284.3 | F31: 2097.6 | G31: 0 | H31: =(E31-F31)*G31 -> 0 | I31: 1.1 | J31: =H31*I31 -> 0 | K31: 12 | L31: 73 | M31: 4.4 | N31: =(L31-K31)*M31 -> 268.4
A32: 25 | B32: 苏清友 | C32: 车间 | D32: 134768 | E32: 389.7 | F32: 284.8 | G32: 80 | H32: =(E32-F32)*G32 -> 8392 | I32: 1.1 | J32: =H32*I32 -> 9231.2 | K32: 0 | L32: 23 | M32: 4.4 | N32: =(L32-K32)*M32 -> 101.2 | Q32: =J32+O32+N32 -> 9332.4 | R32: 9332.4
A33: 26 | B33: 杨文仁 | C33: 车间 | D33: 135939 | E33: 5.2 | F33: 0 | G33: 80 | H33: =(E33-F33)*G33 -> 416 | I33: 1.1 | J33: =H33*I33 -> 457.6 | K33: 0 | L33: 0 | M33: 4.4 | N33: =(L33-K33)*M33 -> 0 | Q33: =J33+O33+N33 -> 457.6
A34: 合计： | J34: =SUM(J3:J33) -> 34266.1 | N34: =SUM(N3:N32) -> 4070 | Q34: =SUM(Q3:Q33) -> 38336.1 | R34: =SUM(R3:R33) -> 37593.67
A35: 餐费： | R35: 1965
A36: 桶装水： | J36: 29638.49 | R36: 105
A37: 方便米饭： | C37: 2箱*36盒 | R37: 346.4
A38: 电费： | R38: 25763.78
J40: =J34-J36 -> 4627.61 | R40: =R34-SUM(R35:R39) -> 9413.49

Sheet 2025年7月水电费
A1: 宏发再生资源市场2025年7月电费收费清单
A2: 序号 | B2: 商户姓名 | C2: 分区 | D2: 电表编号 | E2: 本月电表底数 | F2: 上月电表底数 | G2: 倍率 | H2: 用电量 | I2: 电费单价 | J2: 电费合计 | K2: 补减项 | L2: 备注 | M2: 总计 | N2: 实收
A3: =ROW()-2 -> 1 | B3: 卯声平 | C3: 车间 | D3: 135407 | E3: 1077.3 | F3: 1008.7 | G3: 60 | H3: =(E3-F3)*G3 -> 4116 | I3: 1.1 | J3: =H3*I3 -> 4527.6 | M3: =J3+J4+K3+K4 -> 5210.7 | N3: 5210
C4: 宿舍 | D4: 222933 | E4: 8642 | F4: 8021 | G4: 1 | H4: =(E4-F4)*G4 -> 621 | I4: 1.1 | J4: =H4*I4 -> 683.1
A5: 2 | B5: 王银全 | C5: 车间 | D5: 135406 | E5: 467.2 | F5: 442.1 | G5: 40 | H5: =(E5-F5)*G5 -> 1004 | I5: 1.1 | J5: =H5*I5 -> 1104.4 | M5: =J5+J6+K5+K6 -> 1104.4 | N5: 1104
C6: 宿舍 | D6: SS101 | E6: 184 | F6: 184 | G6: 1 | H6: =(E6-F6)*G6 -> 0 | I6: 1.1 | J6: =H6*I6 -> 0
A7: 3 | B7: 谢贤祥 | C7: 车间 | D7: 135400 | E7: 12.5 | F7: 11.7 | G7: 40 | H7: =(E7-F7)*G7 -> 32 | I7: 1.1 | J7: =H7*I7 -> 35.2 | M7: =J7+J8+K7+K8 -> 138.6 | N7: 138.6
C8: 宿舍 | D8: SS102 | E8: 553 | F8: 459 | G8: 1 | H8: =(E8-F8)*G8 -> 94 | I8: 1.1 | J8: =H8*I8 -> 103.4
A9: 4 | B9: 王银福 | C9: 车间 | D9: 135405 | E9: 362.1 | F9: 335.7 | G9: 40 | H9: =(E9-F9)*G9 -> 1056 | I9: 1.1 | J9: =H9*I9 -> 1161.6 | M9: =J9+K9 -> 1161.6 | N9: 1161
A10: 5 | B10: 王文奇 | C10: 车间 | D10: 135401 | E10: 68.6 | F10: 64 | G10: 20 | H10: =(E10-F10)*G10 -> 92 | I10: 1.1 | J10: =H10*I10 -> 101.2 | M10: =J10+K10 -> 101.2 | N10: 101
A11: 6 | B11: 李兴平 | C11: 车间一 | D11: 135402 | E11: 551.6 | F11: 502.8 | G11: 20 | H11: =(E11-F11)*G11 -> 976 | I11: 1.1 | J11: =H11*I11 -> 1073.6 | M11: =J11+J12+K11+K12 -> 2046 | N11: 2046
C12: 车间二 | D12: 135408 | E12: 223.8 | F12: 201.7 | G12: 40 | H12: =(E12-F12)*G12 -> 884 | I12: 1.1 | J12: =H12*I12 -> 972.4
A13: 7 | B13: 金耀 | C13: 车间 | D13: 136866 | E13: 222.1 | F13: 210.1 | G13: 20 | H13: =(E13-F13)*G13 -> 240 | I13: 1.1 | J13: =H13*I13 -> 264 | M13: =J13+K13 -> 264 | N13: 264
A14: 8 | B14: 代家超 | C14: 车间 | D14: 135847 | E14: 197.7 | F14: 187.6 | G14: 40 | H14: =(E14-F14)*G14 -> 404 | I14: 1.1 | J14: =H14*I14 -> 444.4 | M14: =J14+K14 -> 444.4 | N14: 444
A15: 9 | B15: 崔宇文 | C15: 车间 | D15: 135848 | E15: 606.2 | F15: 545.8 | G15: 40 | H15: =(E15-F15)*G15 -> 2416 | I15: 1.1 | J15: =H15*I15 -> 2657.6 | M15: =J15+K15 -> 2657.6 | N15: 2657.6
A16: 10 | B16: 崔玉文 | C16: 车间 | D16: 135846 | E16: 579.9 | F16: 532.6 | G16: 40 | H16: =(E16-F16)*G16 -> 1892 | I16: 1.1 | J16: =H16*I16 -> 2081.2 | M16: =J16+K16+J17+K17 -> 2644.4 | N16: 2644
D17: 135379 | E17: 6.4 | F17: 0 | G17: 80 | H17: =(E17-F17)*G17 -> 512 | I17: 1.1 | J17: =H17*I17 -> 563.2
A18: 11 | B18: 祖维成 | C18: 车间 | D18: 135845 | E18: 394.2 | F18: 366.5 | G18: 40 | H18: =(E18-F18)*G18 -> 1108 | I18: 1.1 | J18: =H18*I18 -> 1218.8 | M18: =J18+K18 -> 1218.8 | N18: 1218.8 | O18: =N18-M18 -> 0 | P18: 1276 | Q18: =P18-N18 -> 57.2
A19: 12 | B19: 崔大冲 | C19: 车间 | D19: 135844 | E19: 48.4 | F19: 41.9 | G19: 30 | H19: =(E19-F19)*G19 -> 195 | I19: 1.1 | J19: =H19*I19 -> 214.5 | M19: =J19+K19 -> 214.5 | N19: 214.5
A20: 13 | B20: 李世坤 | C20: 车间 | D20: 135844 | E20: 54.5 | F20: 41.2 | G20: 30 | H20: =(E20-F20)*G20 -> 399 | I20: 1.1 | J20: =H20*I20 -> 438.9 | M20: =J20+K20 -> 438.9 | N20: 438
A21: 14 | B21: 代家虎 | C21: 车间 | D21: 135850 | E21: 187 | F21: 179.1 | G21: 30 | H21: =(E21-F21)*G21 -> 237 | I21: 1.1 | J21: =H21*I21 -> 260.7 | M21: =J21+K21 -> 260.7 | N21: 260
A22: 15 | B22: 代家鹏 | C22: 车间 | D22: 135358 | E22: 196.4 | F22: 183.5 | G22: 40 | H22: =(E22-F22)*G22 -> 516 | I22: 1.1 | J22: =H22*I22 -> 567.6 | M22: =J22+K22 -> 567.6 | N22: 567.6
A23: 16 | B23: 代家俊 | C23: 车间 | D23: 135380 | E23: 275 | F23: 256.6 | G23: 40 | H23: =(E23-F23)*G23 -> 736 | I23: 1.1 | J23: =H23*I23 -> 809.6 | M23: =J23+K23 -> 809.6 | N23: 809
A24: 17 | B24: 崔汝波 | C24: 车间 | D24: 135376 | E24: 28.2 | F24: 24.2 | G24: 40 | H24: =(E24-F24)*G24 -> 160 | I24: 1.1 | J24: =H24*I24 -> 176 | M24: =J24+K24 -> 176 | N24: 176
A25: 18 | B25: 崔大洪 | C25: 车间 | D25: CJ101 | E25: 430 | F25: 367 | G25: 1 | H25: =(E25-F25)*G25 -> 63 | I25: 1.1 | J25: =H25*I25 -> 69.3 | M25: =J25+K25 -> 69.3 | N25: 69.3
A26: 19 | B26: 崔大云 | C26: 车间 | D26: CJ102 | E26: 1755 | F26: 1491 | G26: 1 | H26: =(E26-F26)*G26 -> 264 | I26: 1.1 | J26: =H26*I26 -> 290.4 | M26: =J26+K26 -> 290.4 | N26: 290.4
A27: 20 | B27: 冯成 | C27: 车间 | D27: 281917 | E27: 48 | F27: 42.1 | G27: 100 | H27: =(E27-F27)*G27 -> 590 | I27: 1.1 | J27: =H27*I27 -> 649 | M27: =J27+K27 -> 649 | N27: 649
A28: 21 | B28: 崔汝义 | C28: 车间 | D28: 136865 | E28: 281 | F28: 267.5 | G28: 20 | H28: =(E28-F28)*G28 -> 270 | I28: 1.1 | J28: =H28*I28 -> 297 | M28: =J28+K28 -> 297 | N28: 297
A29: 22 | B29: 崔文交 | C29: 车间 | D29: 121780 | E29: 50.5 | F29: 45.6 | G29: 20 | H29: =(E29-F29)*G29 -> 98 | I29: 1.1 | J29: =H29*I29 -> 107.8 | M29: =J29+K29 -> 107.8 | N29: 108
A30: 23 | B30: 马世平 | C30: 车间 | D30: 135940 | E30: 37.5 | F30: 33.9 | G30: 30 | H30: =(E30-F30)*G30 -> 108 | I30: 1.1 | J30: =H30*I30 -> 118.8 | M30: =J30+K30 -> 118.8 | N30: 119
A31: 24 | B31: 崔文洪 | C31: 车间 | D31: 121780 | E31: 2536.7 | F31: 2284.3 | G31: 30 | H31: =(E31-F31)*G31 -> 7572 | I31: 1.1 | J31: =H31*I31 -> 8329.2 | M31: =J31+K31 -> 8329.2
A32: 25 | B32: 苏清友 | C32: 车间 | D32: 134768 | E32: 539.6 | F32: 389.7 | G32: 80 | H32: =(E32-F32)*G32 -> 11992 | I32: 1.1 | J32: =H32*I32 -> 13191.2 | M32: =J32+K32 -> 13191.2 | N32: 13191
A33: 26 | B33: 杨文仁 | C33: 车间 | D33: 135939 | E33: 5.2 | F33: 5.2 | G33: 80 | H33: =(E33-F33)*G33 -> 0 | I33: 1.1 | J33: =H33*I33 -> 0 | K33: 457.6 | L33: 上月欠费 | M33: =J33+K33 -> 457.6 | N33: 457.6
A34: 合计： | J34: =SUM(J3:J33) -> 42511.7 | M34: =SUM(M3:M33) -> 42969.3 | N34: =SUM(N3:N33) -> 34635.4
A35: 餐费： | N35: -1905
A36: 报销： | C36: 余波采购李兴平家防雨改造1吨水泥1车沙 | N36: -590
C37: 蒋安坤采购杨文仁家400A空开(二手) | N37: -100
C38: 采购创峰电缆（300*3+150*2）*54米 铝芯电缆+镀锌线鼻子 | N38: -5230
C39: 配电房门改造(活页、锁扣、挂锁) | N39: -34
C40: 购买夜班晚餐方便面 | N40: =-91.9+-65.9 -> -157.8
...

Sheet 2025年8月电费
A1: 宏发再生资源市场2025年8月电费收费清单
A2: 序号 | B2: 商户姓名 | C2: 分区 | D2: 电表编号 | E2: 本月电表底数 | F2: 上月电表底数 | G2: 倍率 | H2: 用电量 | I2: 电费单价 | J2: 电费合计 | K2: 补减项 | L2: 备注 | M2: 总计 | N2: 实收
A3: =ROW()-2 -> 1 | B3: 卯声平 | C3: 车间 | D3: 135407 | E3: 1189.3 | F3: 1077.3 | G3: 60 | H3: =(E3-F3)*G3 -> 6720 | I3: 1.1 | J3: =H3*I3 -> 7392 | M3: =J3+J4+K3+K4 -> 8055.3 | N3: 8055
C4: 宿舍 | D4: 222933 | E4: 9245 | F4: 8642 | G4: 1 | H4: =(E4-F4)*G4 -> 603 | I4: 1.1 | J4: =H4*I4 -> 663.3
A5: 2 | B5: 王银全 | C5: 车间 | D5: 135406 | E5: 491.4 | F5: 467.2 | G5: 40 | H5: =(E5-F5)*G5 -> 968 | I5: 1.1 | J5: =H5*I5 -> 1064.8 | M5: =J5+K5 -> 1064.8 | N5: 1064
A6: 3 | B6: 谢贤祥 | C6: 车间 | D6: 135400 | E6: 13.3 | F6: 12.5 | G6: 40 | H6: =(E6-F6)*G6 -> 32 | I6: 1.1 | J6: =H6*I6 -> 35.2 | M6: =J6+J7+K6+K7 -> 160.6 | N6: 160.6
C7: 宿舍 | D7: SS102 | E7: 667 | F7: 553 | G7: 1 | H7: =(E7-F7)*G7 -> 114 | I7: 1.1 | J7: =H7*I7 -> 125.4
A8: 4 | B8: 王银福 | C8: 车间 | D8: 135405 | E8: 388.8 | F8: 362.1 | G8: 40 | H8: =(E8-F8)*G8 -> 1068 | I8: 1.1 | J8: =H8*I8 -> 1174.8 | M8: =J8+K8 -> 1174.8 | N8: 1174.8
A9: 5 | B9: 王文奇 | C9: 车间 | D9: 135401 | E9: 73.9 | F9: 68.6 | G9: 20 | H9: =(E9-F9)*G9 -> 106 | I9: 1.1 | J9: =H9*I9 -> 116.6 | M9: =J9+K9 -> 116.6 | N9: 116.6
A10: 6 | B10: 李兴平 | C10: 车间一 | D10: 135402 | E10: 602.7 | F10: 551.6 | G10: 20 | H10: =(E10-F10)*G10 -> 1022 | I10: 1.1 | J10: =H10*I10 -> 1124.2 | M10: =J10+J11+K10+K11 -> 2048.2 | N10: 2049
C11: 车间二 | D11: 135408 | E11: 244.8 | F11: 223.8 | G11: 40 | H11: =(E11-F11)*G11 -> 840 | I11: 1.1 | J11: =H11*I11 -> 924
A12: 7 | B12: 金耀 | C12: 车间 | D12: 136866 | E12: 234.8 | F12: 222.1 | G12: 20 | H12: =(E12-F12)*G12 -> 254 | I12: 1.1 | J12: =H12*I12 -> 279.4 | M12: =J12+K12 -> 279.4 | N12: 279.4
A13: 8 | B13: 代家超 | C13: 车间 | D13: 135847 | E13: 208.5 | F13: 197.7 | G13: 40 | H13: =(E13-F13)*G13 -> 432 | I13: 1.1 | J13: =H13*I13 -> 475.2 | M13: =J13+K13 -> 475.2 | N13: 475
A14: 9 | B14: 崔宇文 | C14: 车间 | D14: 135848 | E14: 662.5 | F14: 606.2 | G14: 40 | H14: =(E14-F14)*G14 -> 2252 | I14: 1.1 | J14: =H14*I14 -> 2477.2 | M14: =J14+K14 -> 2477.2 | N14: 2477.2
A15: 10 | B15: 崔玉文 | C15: 车间 | D15: 135846 | E15: 630.8 | F15: 579.9 | G15: 40 | H15: =(E15-F15)*G15 -> 2036 | I15: 1.1 | J15: =H15*I15 -> 2239.6 | M15: =J15+K15+J16+K16 -> 2741.2 | N15: 2741
D16: 135379 | E16: 12.1 | F16: 6.4 | G16: 80 | H16: =(E16-F16)*G16 -> 456 | I16: 1.1 | J16: =H16*I16 -> 501.6
A17: 11 | B17: 祖维成 | C17: 车间 | D17: 135845 | E17: 422.2 | F17: 394.2 | G17: 40 | H17: =(E17-F17)*G17 -> 1120 | I17: 1.1 | J17: =H17*I17 -> 1232 | M17: =J17+K17 -> 1232 | N17: 1232
A18: 12 | B18: 崔大冲 | C18: 车间 | D18: 135844 | E18: 54.6 | F18: 48.4 | G18: 30 | H18: =(E18-F18)*G18 -> 186 | I18: 1.1 | J18: =H18*I18 -> 204.6 | M18: =J18+K18 -> 204.6 | N18: 204.6
A19: 13 | B19: 李世坤 | C19: 车间 | D19: 135844 | E19: 66.4 | F19: 54.5 | G19: 30 | H19: =(E19-F19)*G19 -> 357 | I19: 1.1 | J19: =H19*I19 -> 392.7 | M19: =J19+K19 -> 392.7 | N19: 392
A20: 14 | B20: 代家虎 | C20: 车间 | D20: 135850 | E20: 197.1 | F20: 187 | G20: 30 | H20: =(E20-F20)*G20 -> 303 | I20: 1.1 | J20: =H20*I20 -> 333.3 | M20: =J20+K20 -> 333.3 | N20: 333
A21: 15 | B21: 代家鹏 | C21: 车间 | D21: 135358 | E21: 211.7 | F21: 196.4 | G21: 40 | H21: =(E21-F21)*G21 -> 612 | I21: 1.1 | J21: =H21*I21 -> 673.2 | M21: =J21+K21 -> 673.2 | N21: 673.2
A22: 16 | B22: 代家静 | C22: 车间 | D22: 135380 | E22: 295.3 | F22: 275 | G22: 40 | H22: =(E22-F22)*G22 -> 812 | I22: 1.1 | J22: =H22*I22 -> 893.2 | M22: =J22+K22 -> 893.2 | N22: 893
A23: 17 | B23: 崔汝波 | C23: 车间 | D23: 135376 | E23: 32.3 | F23: 28.2 | G23: 40 | H23: =(E23-F23)*G23 -> 164 | I23: 1.1 | J23: =H23*I23 -> 180.4 | M23: =J23+K23 -> 180.4 | N23: 180
A24: 18 | B24: 崔大洪 | C24: 车间 | D24: CJ101 | E24: 496 | F24: 430 | G24: 1 | H24: =(E24-F24)*G24 -> 66 | I24: 1.1 | J24: =H24*I24 -> 72.6 | M24: =J24+K24 -> 72.6 | N24: 72.6
A25: 19 | B25: 崔大云 | C25: 车间 | D25: CJ102 | E25: 2099 | F25: 1755 | G25: 1 | H25: =(E25-F25)*G25 -> 344 | I25: 1.1 | J25: =H25*I25 -> 378.4 | M25: =J25+K25 -> 378.4 | N25: 378.4
A26: 20 | B26: 冯成 | C26: 车间 | D26: 281917 | E26: 56.2 | F26: 48 | G26: 100 | H26: =(E26-F26)*G26 -> 820 | I26: 1.1 | J26: =H26*I26 -> 902 | M26: =J26+K26 -> 902 | N26: 902
A27: 21 | B27: 崔汝义 | C27: 车间 | D27: 136865 | E27: 308.6 | F27: 281 | G27: 20 | H27: =(E27-F27)*G27 -> 552 | I27: 1.1 | J27: =H27*I27 -> 607.2 | M27: =J27+K27 -> 607.2 | N27: 607.2
A28: 22 | B28: 崔文交 | C28: 车间 | D28: 121780 | E28: 62 | F28: 50.5 | G28: 20 | H28: =(E28-F28)*G28 -> 230 | I28: 1.1 | J28: =H28*I28 -> 253 | M28: =J28+K28 -> 253 | N28: 253
A29: 23 | B29: 马世平 | C29: 车间 | D29: 135940 | E29: 41 | F29: 37.5 | G29: 30 | H29: =(E29-F29)*G29 -> 105 | I29: 1.1 | J29: =H29*I29 -> 115.5 | M29: =J29+K29 -> 115.5 | N29: 16
A30: 24 | B30: 崔文洪 | C30: 车间 | D30: 121780 | E30: 2772.3 | F30: 2536.7 | G30: 30 | H30: =(E30-F30)*G30 -> 7068 | I30: 1.1 | J30: =H30*I30 -> 7774.8 | K30: -7774.8 | M30: =J30+K30 -> 1.0004442e-11
A31: 25 | B31: 苏清友 | C31: 车间 | D31: 134768 | E31: 691.1 | F31: 539.6 | G31: 80 | H31: =(E31-F31)*G31 -> 12120 | I31: 1.1 | J31: =H31*I31 -> 13332 | M31: =J31+K31 -> 13332 | N31: 13332
A32: 26 | B32: 杨文仁 | C32: 车间 | D32: 135939 | E32: 32.4 | F32: 5.2 | G32: 80 | H32: =(E32-F32)*G32 -> 2176 | I32: 1.1 | J32: =H32*I32 -> 2393.6 | M32: =J32+K32 -> 2393.6 | N32: 2393.6
A33: 27 | B33: 创峰建材 | C33: 车间 | D33: 施工用电 | E33: 1109 | F33: 256 | G33: 1 | H33: =(E33-F33)*G33 -> 853 | I33: 1.1 | J33: =H33*I33 -> 938.3 | M33: =J33+K33 -> 938.3 | N33: 938
A34: 合计： | J34: =SUM(J3:J32) -> 48331.8 | M34: =SUM(M3:M33) -> 41495.3 | N34: =SUM(N3:N33) -> 41393.2 | O34: =M34-M30 -> 41495.3
A35: 餐费： | N35: -1815
A36: 报销： | C36: 垃圾运费16*380=6080 | N36: -6080
C37: 夜班方便面104.9+65.9+83.9 | N37: =-104.9-65.9-83.9 -> -254.7
C38: 7月电费 | N38: -24324.87
C39: 仓库隔间材料-余波 | N39: -1733
C40: 仓库隔断工钱-余波 | N40: -700
...

Sheet 2025年9月电费
A1: 宏发再生资源市场2025年9月电费收费清单
A2: 序号 | B2: 商户姓名 | C2: 分区 | D2: 电表编号 | E2: 本月电表底数 | F2: 上月电表底数 | G2: 倍率 | H2: 用电量 | I2: 电费单价 | J2: 电费合计 | K2: 补减项 | L2: 备注 | M2: 总计 | N2: 实收
A3: =ROW()-2 -> 1 | B3: 卯声平 | C3: 车间 | D3: 135407 | E3: 1253.5 | F3: 1189.3 | G3: 60 | H3: =(E3-F3)*G3 -> 3852 | I3: 1.1 | J3: =H3*I3 -> 4237.2 | M3: =J3+J4+K3+K4 -> 4877.4 | N3: 4877.4
C4: 宿舍 | D4: 222933 | E4: 9827 | F4: 9245 | G4: 1 | H4: =(E4-F4)*G4 -> 582 | I4: 1.1 | J4: =H4*I4 -> 640.2
A5: 2 | B5: 王银全 | C5: 车间 | D5: 135406 | E5: 517.5 | F5: 491.4 | G5: 40 | H5: =(E5-F5)*G5 -> 1044 | I5: 1.1 | J5: =H5*I5 -> 1148.4 | M5: =J5+K5 -> 1148.4 | N5: 1148
A6: 3 | B6: 谢贤祥 | C6: 车间 | D6: 135400 | E6: 13.8 | F6: 13.3 | G6: 40 | H6: =(E6-F6)*G6 -> 20 | I6: 1.1 | J6: =H6*I6 -> 22 | M6: =J6+J7+K6+K7 -> 85.8 | N6: 85.8
C7: 宿舍 | D7: SS102 | E7: 725 | F7: 667 | G7: 1 | H7: =(E7-F7)*G7 -> 58 | I7: 1.1 | J7: =H7*I7 -> 63.8
A8: 4 | B8: 王银福 | C8: 车间 | D8: 135405 | E8: 417.2 | F8: 388.8 | G8: 40 | H8: =(E8-F8)*G8 -> 1136 | I8: 1.1 | J8: =H8*I8 -> 1249.6 | M8: =J8+K8 -> 1249.6 | N8: 1249
A9: 5 | B9: 王文奇 | C9: 车间 | D9: 135401 | E9: 78.4 | F9: 73.9 | G9: 20 | H9: =(E9-F9)*G9 -> 90 | I9: 1.1 | J9: =H9*I9 -> 99 | M9: =J9+K9 -> 99 | N9: 99
A10: 6 | B10: 李兴平 | C10: 车间一 | D10: 135402 | E10: 649.9 | F10: 602.7 | G10: 20 | H10: =(E10-F10)*G10 -> 944 | I10: 1.1 | J10: =H10*I10 -> 1038.4 | M10: =J10+J11+K10+K11 -> 1830.4 | N10: 1830
C11: 车间二 | D11: 135408 | E11: 262.8 | F11: 244.8 | G11: 40 | H11: =(E11-F11)*G11 -> 720 | I11: 1.1 | J11: =H11*I11 -> 792
A12: 7 | B12: 金耀 | C12: 车间 | D12: 136866 | E12: 248.7 | F12: 234.8 | G12: 20 | H12: =(E12-F12)*G12 -> 278 | I12: 1.1 | J12: =H12*I12 -> 305.8 | M12: =J12+K12 -> 305.8 | N12: 305.5
A13: 8 | B13: 代家超 | C13: 车间 | D13: 135847 | E13: 218.3 | F13: 208.5 | G13: 40 | H13: =(E13-F13)*G13 -> 392 | I13: 1.1 | J13: =H13*I13 -> 431.2 | M13: =J13+K13 -> 431.2 | N13: 431
A14: 9 | B14: 崔宇文 | C14: 车间 | D14: 135848 | E14: 722.7 | F14: 662.5 | G14: 40 | H14: =(E14-F14)*G14 -> 2408 | I14: 1.1 | J14: =H14*I14 -> 2648.8 | M14: =J14+K14 -> 2648.8 | N14: 2648.8
A15: 10 | B15: 崔玉文 | C15: 车间 | D15: 135846 | E15: 678.9 | F15: 630.8 | G15: 40 | H15: =(E15-F15)*G15 -> 1924 | I15: 1.1 | J15: =H15*I15 -> 2116.4 | M15: =J15+K15+J16+K16 -> 2882 | N15: 2882
D16: 135379 | E16: 20.8 | F16: 12.1 | G16: 80 | H16: =(E16-F16)*G16 -> 696 | I16: 1.1 | J16: =H16*I16 -> 765.6
A17: 11 | B17: 祖维成 | C17: 车间 | D17: 135845 | E17: 448.8 | F17: 422.2 | G17: 40 | H17: =(E17-F17)*G17 -> 1064 | I17: 1.1 | J17: =H17*I17 -> 1170.4 | M17: =J17+K17 -> 1170.4 | N17: 1170
A18: 12 | B18: 崔大冲 | C18: 车间 | D18: 135844 | E18: 62.3 | F18: 54.6 | G18: 30 | H18: =(E18-F18)*G18 -> 231 | I18: 1.1 | J18: =H18*I18 -> 254.1 | M18: =J18+K18 -> 254.1 | N18: 254.1
A19: 13 | B19: 李世坤 | C19: 车间 | D19: 135844 | E19: 77.5 | F19: 66.4 | G19: 30 | H19: =(E19-F19)*G19 -> 333 | I19: 1.1 | J19: =H19*I19 -> 366.3 | M19: =J19+K19 -> 366.3 | N19: 366.3
A20: 14 | B20: 代家虎 | C20: 车间 | D20: 135850 | E20: 207 | F20: 197.1 | G20: 30 | H20: =(E20-F20)*G20 -> 297 | I20: 1.1 | J20: =H20*I20 -> 326.7 | M20: =J20+K20 -> 326.7 | N20: 326
A21: 15 | B21: 代家鹏 | C21: 车间 | D21: 135358 | E21: 222.4 | F21: 211.7 | G21: 40 | H21: =(E21-F21)*G21 -> 428 | I21: 1.1 | J21: =H21*I21 -> 470.8 | M21: =J21+K21 -> 470.8 | N21: 470
A22: 16 | B22: 代家静 | C22: 车间 | D22: 135380 | E22: 311.4 | F22: 295.3 | G22: 40 | H22: =(E22-F22)*G22 -> 644 | I22: 1.1 | J22: =H22*I22 -> 708.4 | M22: =J22+K22 -> 708.4 | N22: 708
A23: 17 | B23: 崔汝波 | C23: 车间 | D23: 135376 | E23: 36.7 | F23: 32.3 | G23: 40 | H23: =(E23-F23)*G23 -> 176 | I23: 1.1 | J23: =H23*I23 -> 193.6 | M23: =J23+K23 -> 193.6 | N23: 194
A24: 18 | B24: 崔大洪 | C24: 车间 | D24: CJ101 | E24: 561 | F24: 496 | G24: 1 | H24: =(E24-F24)*G24 -> 65 | I24: 1.1 | J24: =H24*I24 -> 71.5 | M24: =J24+K24 -> 71.5 | N24: 71.5
A25: 19 | B25: 崔大云 | C25: 车间 | D25: CJ102 | E25: 2494 | F25: 2099 | G25: 1 | H25: =(E25-F25)*G25 -> 395 | I25: 1.1 | J25: =H25*I25 -> 434.5 | M25: =J25+K25 -> 434.5 | N25: 434.5
A26: 20 | B26: 冯成 | C26: 车间 | D26: 281917 | E26: 68 | F26: 56.2 | G26: 100 | H26: =(E26-F26)*G26 -> 1180 | I26: 1.1 | J26: =H26*I26 -> 1298 | M26: =J26+K26 -> 1298 | N26: 1298
A27: 21 | B27: 崔汝义 | C27: 车间 | D27: 136865 | E27: 327 | F27: 308.6 | G27: 20 | H27: =(E27-F27)*G27 -> 368 | I27: 1.1 | J27: =H27*I27 -> 404.8 | M27: =J27+K27 -> 404.8 | N27: 404
A28: 22 | B28: 崔文交 | C28: 车间 | D28: 121780 | E28: 70 | F28: 62 | G28: 20 | H28: =(E28-F28)*G28 -> 160 | I28: 1.1 | J28: =H28*I28 -> 176 | M28: =J28+K28 -> 176 | N28: 176
A29: 23 | B29: 马世平 | C29: 车间 | D29: 135940 | E29: 44.7 | F29: 41 | G29: 30 | H29: =(E29-F29)*G29 -> 111 | I29: 1.1 | J29: =H29*I29 -> 122.1 | M29: =J29+K29 -> 122.1 | N29: 123
A30: 24 | B30: 崔文洪 | C30: 车间 | D30: 121780 | E30: 2997.5 | F30: 2772.3 | G30: 30 | H30: =(E30-F30)*G30 -> 6756 | I30: 1.1 | J30: =H30*I30 -> 7431.6 | M30: 0
A31: 25 | B31: 苏清友 | C31: 车间 | D31: 134768 | E31: 839.3 | F31: 691.1 | G31: 80 | H31: =(E31-F31)*G31 -> 11856 | I31: 1.1 | J31: =H31*I31 -> 13041.6 | M31: =J31+K31 -> 13041.6 | N31: 13041
A32: 26 | B32: 杨文仁 | C32: 车间 | D32: 135939 | E32: 66.4 | F32: 32.4 | G32: 80 | H32: =(E32-F32)*G32 -> 2720 | I32: 1.1 | J32: =H32*I32 -> 2992 | M32: =J32+K32 -> 2992 | N32: 2992
A33: 27 | B33: 创峰建材 | C33: 车间 | D33: 施工用电 | E33: 17.1 | F33: 0 | G33: 80 | H33: =(E33-F33)*G33 -> 1368 | I33: 1.1 | J33: =H33*I33 -> 1504.8 | M33: =J33+K33 -> 1504.8 | N33: 1504.8 | O33: =N33-M33 -> 0
A34: 合计： | J34: =SUM(J3:J33) -> 46525.6 | M34: =SUM(M3:M33) -> 39094 | N34: =SUM(N3:N33) -> 39089.7 | O34: =M34-M30 -> 39094
A35: 餐费： | N35: -1980
A36: 报销： | C36: 崔文洪挖机装垃圾工钱 | N36: -2000
C37: 桶装水10桶*7元 | N37: -70
C38: 8月代缴电费 | N38: -29977.06
C39: 全铜并沟线夹*5（李兴平改造用） | N39: -75.65
C40: 冯成彩钢瓦维修工钱 | N40: -600
...

Sheet 2025年10月电费
A1: 宏发再生资源市场2025年10月电费收费清单
A2: 序号 | B2: 商户姓名 | C2: 分区 | D2: 电表编号 | E2: 本月电表底数 | F2: 上月电表底数 | G2: 倍率 | H2: 用电量 | I2: 电费单价 | J2: 电费合计 | K2: 补减项 | L2: 备注 | M2: 总计 | N2: 实收
A3: =ROW()-2 -> 1 | B3: 卯声平 | C3: 车间 | D3: 135407 | E3: 1319.7 | F3: 1253.5 | G3: 60 | H3: =(E3-F3)*G3 -> 3972 | I3: 1.1 | J3: =H3*I3 -> 4369.2 | M3: =J3+J4+K3+K4 -> 4999.5 | N3: 5000
C4: 宿舍 | D4: 222933 | E4: 10400 | F4: 9827 | G4: 1 | H4: =(E4-F4)*G4 -> 573 | I4: 1.1 | J4: =H4*I4 -> 630.3
A5: 2 | B5: 王银全 | C5: 车间 | D5: 135406 | E5: 539.3 | F5: 517.5 | G5: 40 | H5: =(E5-F5)*G5 -> 872 | I5: 1.1 | J5: =H5*I5 -> 959.2 | M5: =J5+K5 -> 959.2 | N5: 959
A6: 3 | B6: 谢贤祥 | C6: 车间 | D6: 135400 | E6: 14.3 | F6: 13.8 | G6: 40 | H6: =(E6-F6)*G6 -> 20 | I6: 1.1 | J6: =H6*I6 -> 22 | M6: =J6+J7+K6+K7 -> 73.7 | N6: 73.7
C7: 宿舍 | D7: SS102 | E7: 772 | F7: 725 | G7: 1 | H7: =(E7-F7)*G7 -> 47 | I7: 1.1 | J7: =H7*I7 -> 51.7
A8: 4 | B8: 王银福 | C8: 车间 | D8: 135405 | E8: 441 | F8: 417.2 | G8: 40 | H8: =(E8-F8)*G8 -> 952 | I8: 1.1 | J8: =H8*I8 -> 1047.2 | M8: =J8+K8 -> 1047.2 | N8: 1047
A9: 5 | B9: 王文奇 | C9: 车间 | D9: 135401 | E9: 84.4 | F9: 78.4 | G9: 20 | H9: =(E9-F9)*G9 -> 120 | I9: 1.1 | J9: =H9*I9 -> 132 | M9: =J9+K9 -> 132 | N9: 132
A10: 6 | B10: 李兴平 | C10: 车间一 | D10: 135402 | E10: 697.7 | F10: 649.9 | G10: 20 | H10: =(E10-F10)*G10 -> 956 | I10: 1.1 | J10: =H10*I10 -> 1051.6 | M10: =J10+J11+K10+K11 -> 1786.4 | N10: 1786
C11: 车间二 | D11: 135408 | E11: 279.5 | F11: 262.8 | G11: 40 | H11: =(E11-F11)*G11 -> 668 | I11: 1.1 | J11: =H11*I11 -> 734.8
A12: 7 | B12: 金耀 | C12: 车间 | D12: 136866 | E12: 258.1 | F12: 248.7 | G12: 20 | H12: =(E12-F12)*G12 -> 188 | I12: 1.1 | J12: =H12*I12 -> 206.8 | M12: =J12+K12 -> 206.8 | N12: 207
A13: 8 | B13: 代家超 | C13: 车间 | D13: 135847 | E13: 226.5 | F13: 218.3 | G13: 40 | H13: =(E13-F13)*G13 -> 328 | I13: 1.1 | J13: =H13*I13 -> 360.8 | M13: =J13+K13 -> 360.8 | N13: 360
A14: 9 | B14: 崔宇文 | C14: 车间 | D14: 135848 | E14: 783.2 | F14: 722.7 | G14: 40 | H14: =(E14-F14)*G14 -> 2420 | I14: 1.1 | J14: =H14*I14 -> 2662 | M14: =J14+K14 -> 2662 | N14: 2662
A15: 10 | B15: 崔玉文 | C15: 车间 | D15: 135846 | E15: 721.1 | F15: 678.9 | G15: 40 | H15: =(E15-F15)*G15 -> 1688 | I15: 1.1 | J15: =H15*I15 -> 1856.8 | M15: =J15+K15+J16+K16 -> 2200 | N15: 2200
D16: 135379 | E16: 24.7 | F16: 20.8 | G16: 80 | H16: =(E16-F16)*G16 -> 312 | I16: 1.1 | J16: =H16*I16 -> 343.2
A17: 11 | B17: 祖维成 | C17: 车间 | D17: 135845 | E17: 476.5 | F17: 448.8 | G17: 40 | H17: =(E17-F17)*G17 -> 1108 | I17: 1.1 | J17: =H17*I17 -> 1218.8 | M17: =J17+K17 -> 1218.8 | N17: 1218
A18: 12 | B18: 崔大冲 | C18: 车间 | D18: 135844 | E18: 68.2 | F18: 62.3 | G18: 30 | H18: =(E18-F18)*G18 -> 177 | I18: 1.1 | J18: =H18*I18 -> 194.7 | M18: =J18+K18 -> 194.7 | N18: 194.7
A19: 13 | B19: 李世坤 | C19: 车间 | D19: 135844 | E19: 85.6 | F19: 77.5 | G19: 30 | H19: =(E19-F19)*G19 -> 243 | I19: 1.1 | J19: =H19*I19 -> 267.3 | M19: =J19+K19 -> 267.3 | N19: 267.3
A20: 14 | B20: 代家虎 | C20: 车间 | D20: 135850 | E20: 215.3 | F20: 207 | G20: 30 | H20: =(E20-F20)*G20 -> 249 | I20: 1.1 | J20: =H20*I20 -> 273.9 | M20: =J20+K20 -> 273.9 | N20: 273
A21: 15 | B21: 代家鹏 | C21: 车间 | D21: 135358 | E21: 233.3 | F21: 222.4 | G21: 40 | H21: =(E21-F21)*G21 -> 436 | I21: 1.1 | J21: =H21*I21 -> 479.6 | M21: =J21+K21 -> 479.6 | N21: 479.6
A22: 16 | B22: 代家静 | C22: 车间 | D22: 135380 | E22: 332.1 | F22: 311.4 | G22: 40 | H22: =(E22-F22)*G22 -> 828 | I22: 1.1 | J22: =H22*I22 -> 910.8 | M22: =J22+K22 -> 910.8 | N22: 910
A23: 17 | B23: 崔汝波 | C23: 车间 | D23: 135376 | E23: 39.6 | F23: 36.7 | G23: 40 | H23: =(E23-F23)*G23 -> 116 | I23: 1.1 | J23: =H23*I23 -> 127.6 | M23: =J23+K23 -> 127.6 | N23: 128
A24: 18 | B24: 崔大洪 | C24: 车间 | D24: CJ101 | E24: 617 | F24: 561 | G24: 1 | H24: =(E24-F24)*G24 -> 56 | I24: 1.1 | J24: =H24*I24 -> 61.6 | M24: =J24+K24 -> 61.6 | N24: 61.6
A25: 19 | B25: 崔大云 | C25: 车间 | D25: CJ102 | E25: 2750 | F25: 2494 | G25: 1 | H25: =(E25-F25)*G25 -> 256 | I25: 1.1 | J25: =H25*I25 -> 281.6 | M25: =J25+K25 -> 281.6 | N25: 281.6
A26: 20 | B26: 冯成 | C26: 车间 | D26: 281917 | E26: 77.8 | F26: 68 | G26: 100 | H26: =(E26-F26)*G26 -> 980 | I26: 1.1 | J26: =H26*I26 -> 1078 | M26: =J26+K26 -> 1078 | N26: 1078
A27: 21 | B27: 崔汝义 | C27: 车间 | D27: 136865 | E27: 343.6 | F27: 327 | G27: 20 | H27: =(E27-F27)*G27 -> 332 | I27: 1.1 | J27: =H27*I27 -> 365.2 | M27: =J27+K27 -> 365.2 | N27: 365.2
A28: 22 | B28: 崔文交 | C28: 车间 | D28: 121780 | E28: 76.7 | F28: 70 | G28: 20 | H28: =(E28-F28)*G28 -> 134 | I28: 1.1 | J28: =H28*I28 -> 147.4 | M28: =J28+K28 -> 147.4 | N28: 148
A29: 23 | B29: 马世平 | C29: 车间 | D29: 135940 | E29: 49.6 | F29: 44.7 | G29: 30 | H29: =(E29-F29)*G29 -> 147 | I29: 1.1 | J29: =H29*I29 -> 161.7 | M29: =J29+K29 -> 161.7 | N29: 162
A30: 24 | B30: 崔文洪 | C30: 车间 | D30: 121780 | E30: 3253.7 | F30: 2997.5 | G30: 30 | H30: =(E30-F30)*G30 -> 7686 | I30: 1.1 | J30: =H30*I30 -> 8454.6 | M30: 0
A31: 25 | B31: 苏清友 | C31: 车间 | D31: 134768 | E31: 938.3 | F31: 839.3 | G31: 80 | H31: =(E31-F31)*G31 -> 7920 | I31: 1.1 | J31: =H31*I31 -> 8712 | M31: =J31+K31 -> 8712 | N31: 8712
A32: 26 | B32: 杨文仁 | C32: 宿舍 | E32: 24 | F32: 0 | G32: 1 | H32: =(E32-F32)*G32 -> 24 | I32: 1.1 | J32: 26.4 | K32: 12 | L32: 水费12元 | M32: =J32+K32+J33+K33 -> 4165.6 | N32: 4165.6
A33: 27 | C33: 车间 | D33: 135939 | E33: 113.3 | F33: 66.4 | G33: 80 | H33: =(E33-F33)*G33 -> 3752 | I33: 1.1 | J33: =H33*I33 -> 4127.2
A34: 28 | B34: 创峰建材 | C34: 车间 | D34: 施工用电 | E34: 39.4 | F34: 17.1 | G34: 80 | H34: =(E34-F34)*G34 -> 1784 | I34: 1.1 | J34: =H34*I34 -> 1962.4 | M34: =J34+K34 -> 1962.4 | N34: 1962 | O34: =N34-M34 -> -0.4
A35: 合计： | J35: =SUM(J3:J34) -> 43278.4 | M35: =SUM(M3:M34) -> 34835.8 | N35: =SUM(N3:N34) -> 34833.3 | O35: =M35-M30 -> 34835.8
A36: 餐费： | N36: -1895
A37: 报销： | C37: 购买中性笔20支*2盒 | N37: -34.7
C38: 桶装水10桶*7元 | N38: -70
C39: 9月代缴电费 | N39: -27310.52
C40: 取暖炉桌垫 | N40: -20 | P40: 冯成彩钢瓦维修
...

Sheet 2025年11月电费
A1: 宏发再生资源市场2025年11月电费收费清单
A2: 序号 | B2: 商户姓名 | C2: 分区 | D2: 电表编号 | E2: 本月电表底数 | F2: 上月电表底数 | G2: 倍率 | H2: 用电量 | I2: 电费单价 | J2: 电费合计 | K2: 补减项 | L2: 备注 | M2: 总计 | N2: 实收
A3: =ROW()-2 -> 1 | B3: 卯声平 | C3: 车间 | D3: 135407 | E3: 1398.9 | F3: 1319.7 | G3: 60 | H3: =(E3-F3)*G3 -> 4752 | I3: 1.1 | J3: =H3*I3 -> 5227.2 | M3: =J3+J4+K3+K4 -> 6619.8 | N3: 6620
C4: 宿舍 | D4: 222933 | E4: 11666 | F4: 10400 | G4: 1 | H4: =(E4-F4)*G4 -> 1266 | I4: 1.1 | J4: =H4*I4 -> 1392.6
A5: 2 | B5: 王银全 | C5: 车间 | D5: 135406 | E5: 579.7 | F5: 539.3 | G5: 40 | H5: =(E5-F5)*G5 -> 1616 | I5: 1.1 | J5: =H5*I5 -> 1777.6 | M5: =J5+K5 -> 1777.6 | N5: 1777
A6: 3 | B6: 谢贤祥 | C6: 车间 | D6: 135400 | E6: 15 | F6: 14.3 | G6: 40 | H6: =(E6-F6)*G6 -> 28 | I6: 1.1 | J6: =H6*I6 -> 30.8 | M6: =J6+J7+K6+K7 -> 108.9 | N6: 108.9
C7: 宿舍 | D7: SS102 | E7: 843 | F7: 772 | G7: 1 | H7: =(E7-F7)*G7 -> 71 | I7: 1.1 | J7: =H7*I7 -> 78.1
A8: 4 | B8: 王银福 | C8: 车间 | D8: 135405 | E8: 474.7 | F8: 441 | G8: 40 | H8: =(E8-F8)*G8 -> 1348 | I8: 1.1 | J8: =H8*I8 -> 1482.8 | M8: =J8+K8 -> 1482.8 | N8: 1482
A9: 5 | B9: 王文奇 | C9: 车间 | D9: 135401 | E9: 92.7 | F9: 84.4 | G9: 20 | H9: =(E9-F9)*G9 -> 166 | I9: 1.1 | J9: =H9*I9 -> 182.6 | M9: =J9+K9 -> 182.6 | N9: 182.6
A10: 6 | B10: 李兴平 | C10: 车间一 | D10: 135402 | E10: 750.1 | F10: 697.7 | G10: 20 | H10: =(E10-F10)*G10 -> 1048 | I10: 1.1 | J10: =H10*I10 -> 1152.8 | M10: =J10+J11+K10+K11+J12+K12 -> 2393.6 | N10: 2393.6
C11: 车间二 | D11: 135408 | E11: 302.4 | F11: 279.5 | G11: 40 | H11: =(E11-F11)*G11 -> 916 | I11: 1.1 | J11: =H11*I11 -> 1007.6
C12: 车间三 | D12: 120279 | E12: 5.3 | F12: 0 | G12: 40 | H12: =(E12-F12)*G12 -> 212 | I12: 1.1 | J12: =H12*I12 -> 233.2
A13: 7 | B13: 金耀 | C13: 车间 | D13: 136866 | E13: 264.7 | F13: 258.1 | G13: 20 | H13: =(E13-F13)*G13 -> 132 | I13: 1.1 | J13: =H13*I13 -> 145.2 | M13: =J13+K13 -> 145.2 | N13: 145.2
A14: 8 | B14: 代家超 | C14: 车间 | D14: 135847 | E14: 239.5 | F14: 226.5 | G14: 40 | H14: =(E14-F14)*G14 -> 520 | I14: 1.1 | J14: =H14*I14 -> 572 | M14: =J14+K14 -> 572 | N14: 572
A15: 9 | B15: 崔宇文 | C15: 车间 | D15: 135848 | E15: 844 | F15: 783.2 | G15: 40 | H15: =(E15-F15)*G15 -> 2432 | I15: 1.1 | J15: =H15*I15 -> 2675.2 | M15: =J15+K15 -> 2675.2 | N15: 2675.2
A16: 10 | B16: 崔玉文 | C16: 车间 | D16: 135846 | E16: 768.8 | F16: 721.1 | G16: 40 | H16: =(E16-F16)*G16 -> 1908 | I16: 1.1 | J16: =H16*I16 -> 2098.8 | M16: =J16+K16+J17+K17 -> 3885.2 | N16: 3885
D17: 135379 | E17: 45 | F17: 24.7 | G17: 80 | H17: =(E17-F17)*G17 -> 1624 | I17: 1.1 | J17: =H17*I17 -> 1786.4
A18: 11 | B18: 祖维成 | C18: 车间 | D18: 135845 | E18: 514.6 | F18: 476.5 | G18: 40 | H18: =(E18-F18)*G18 -> 1524 | I18: 1.1 | J18: =H18*I18 -> 1676.4 | M18: =J18+K18 -> 1676.4 | N18: 1676
A19: 12 | B19: 崔大冲 | C19: 车间 | D19: 135844 | E19: 75.2 | F19: 68.2 | G19: 30 | H19: =(E19-F19)*G19 -> 210 | I19: 1.1 | J19: =H19*I19 -> 231 | M19: =J19+K19 -> 231 | N19: 231
A20: 13 | B20: 李世坤 | C20: 车间 | D20: 135844 | E20: 96.8 | F20: 85.6 | G20: 30 | H20: =(E20-F20)*G20 -> 336 | I20: 1.1 | J20: =H20*I20 -> 369.6 | M20: =J20+K20 -> 369.6 | N20: 369.6
A21: 14 | B21: 代家虎 | C21: 车间 | D21: 135850 | E21: 223.9 | F21: 215.3 | G21: 30 | H21: =(E21-F21)*G21 -> 258 | I21: 1.1 | J21: =H21*I21 -> 283.8 | M21: =J21+K21 -> 283.8 | N21: 283
A22: 15 | B22: 代家鹏 | C22: 车间 | D22: 135358 | E22: 247.9 | F22: 233.3 | G22: 40 | H22: =(E22-F22)*G22 -> 584 | I22: 1.1 | J22: =H22*I22 -> 642.4 | M22: =J22+K22 -> 642.4 | N22: 642
A23: 16 | B23: 代家静 | C23: 车间 | D23: 135380 | E23: 354.3 | F23: 332.1 | G23: 40 | H23: =(E23-F23)*G23 -> 888 | I23: 1.1 | J23: =H23*I23 -> 976.8 | M23: =J23+K23 -> 976.8 | N23: 976
A24: 17 | B24: 崔汝波 | C24: 车间 | D24: 135376 | E24: 41.7 | F24: 39.6 | G24: 40 | H24: =(E24-F24)*G24 -> 84 | I24: 1.1 | J24: =H24*I24 -> 92.4 | M24: =J24+K24 -> 92.4 | N24: 93
A25: 18 | B25: 崔大洪 | C25: 车间 | D25: CJ101 | E25: 676 | F25: 617 | G25: 1 | H25: =(E25-F25)*G25 -> 59 | I25: 1.1 | J25: =H25*I25 -> 64.9 | M25: =J25+K25 -> 64.9 | N25: 65
A26: 19 | B26: 崔大云 | C26: 车间 | D26: CJ102 | E26: 3040 | F26: 2750 | G26: 1 | H26: =(E26-F26)*G26 -> 290 | I26: 1.1 | J26: =H26*I26 -> 319 | M26: =J26+K26 -> 319 | N26: 319
A27: 20 | B27: 冯成 | C27: 车间 | D27: 281917 | E27: 92.1 | F27: 77.8 | G27: 100 | H27: =(E27-F27)*G27 -> 1430 | I27: 1.1 | J27: =H27*I27 -> 1573 | M27: =J27+K27 -> 1573 | N27: 1573
A28: 21 | B28: 崔汝义 | C28: 车间 | D28: 136865 | E28: 359 | F28: 343.6 | G28: 20 | H28: =(E28-F28)*G28 -> 308 | I28: 1.1 | J28: =H28*I28 -> 338.8 | M28: =J28+K28 -> 338.8 | N28: 338.8
A29: 22 | B29: 崔文交 | C29: 车间 | D29: 121780 | E29: 82.9 | F29: 76.7 | G29: 20 | H29: =(E29-F29)*G29 -> 124 | I29: 1.1 | J29: =H29*I29 -> 136.4 | M29: =J29+K29 -> 136.4 | N29: 137
A30: 23 | B30: 马世平 | C30: 车间 | D30: 135940 | E30: 55.7 | F30: 49.6 | G30: 30 | H30: =(E30-F30)*G30 -> 183 | I30: 1.1 | J30: =H30*I30 -> 201.3 | M30: =J30+K30 -> 201.3 | N30: 202
A31: 24 | B31: 崔文洪 | C31: 车间 | D31: 121780 | E31: 3497.2 | F31: 3253.7 | G31: 30 | H31: =(E31-F31)*G31 -> 7305 | I31: 1.1 | J31: =H31*I31 -> 8035.5 | M31: 0 | N31: 0
A32: 25 | B32: 苏清友 | C32: 车间 | D32: 134768 | E32: 970.5 | F32: 938.3 | G32: 80 | H32: =(E32-F32)*G32 -> 2576 | I32: 1.1 | J32: =H32*I32 -> 2833.6 | M32: =J32+K32 -> 2833.6 | N32: 2833
A33: 27 | B33: 杨文仁 | C33: 车间 | D33: 135939 | E33: 161.6 | F33: 113.3 | G33: 80 | H33: =(E33-F33)*G33 -> 3864 | I33: 1.1 | J33: =H33*I33 -> 4250.4 | M33: =J33+K33 -> 4250.4 | N33: 4251
